Traceback (most recent call last):
  File "/home/vboxuser/Documents/Math-Odyssey/gen_formalizer/.venv/lib/python3.13/site-packages/litellm/llms/vertex_ai/gemini/vertex_and_google_ai_studio_gemini.py", line 1890, in completion
    response = client.post(url=url, headers=headers, json=data)  # type: ignore
  File "/home/vboxuser/Documents/Math-Odyssey/gen_formalizer/.venv/lib/python3.13/site-packages/litellm/llms/custom_httpx/http_handler.py", line 780, in post
    raise e
  File "/home/vboxuser/Documents/Math-Odyssey/gen_formalizer/.venv/lib/python3.13/site-packages/litellm/llms/custom_httpx/http_handler.py", line 762, in post
    response.raise_for_status()
    ~~~~~~~~~~~~~~~~~~~~~~~~~^^
  File "/home/vboxuser/Documents/Math-Odyssey/gen_formalizer/.venv/lib/python3.13/site-packages/httpx/_models.py", line 829, in raise_for_status
    raise HTTPStatusError(message, request=request, response=self)
httpx.HTTPStatusError: Server error '503 Service Unavailable' for url 'https://generativelanguage.googleapis.com/v1beta/models/gemini-2.5-flash:generateContent?key=AIzaSyDoL-8LOr6PUL1KLHCAQsSWl9uJ1PsMD7o'
For more information check: https://developer.mozilla.org/en-US/docs/Web/HTTP/Status/503

During handling of the above exception, another exception occurred:

Traceback (most recent call last):
  File "/home/vboxuser/Documents/Math-Odyssey/gen_formalizer/.venv/lib/python3.13/site-packages/litellm/main.py", line 2606, in completion
    response = vertex_chat_completion.completion(  # type: ignore
        model=model,
    ...<17 lines>...
        extra_headers=extra_headers,
    )
  File "/home/vboxuser/Documents/Math-Odyssey/gen_formalizer/.venv/lib/python3.13/site-packages/litellm/llms/vertex_ai/gemini/vertex_and_google_ai_studio_gemini.py", line 1894, in completion
    raise VertexAIError(
    ...<3 lines>...
    )
litellm.llms.vertex_ai.common_utils.VertexAIError: {
  "error": {
    "code": 503,
    "message": "The model is overloaded. Please try again later.",
    "status": "UNAVAILABLE"
  }
}


During handling of the above exception, another exception occurred:

Traceback (most recent call last):
  File "/home/vboxuser/Documents/Math-Odyssey/gen_formalizer/src/gen_formalizer/main.py", line 29, in run
    result = GenFormalizer().crew().kickoff(inputs=inputs)
  File "/home/vboxuser/Documents/Math-Odyssey/gen_formalizer/.venv/lib/python3.13/site-packages/crewai/crew.py", line 661, in kickoff
    result = self._run_sequential_process()
  File "/home/vboxuser/Documents/Math-Odyssey/gen_formalizer/.venv/lib/python3.13/site-packages/crewai/crew.py", line 772, in _run_sequential_process
    return self._execute_tasks(self.tasks)
           ~~~~~~~~~~~~~~~~~~~^^^^^^^^^^^^
  File "/home/vboxuser/Documents/Math-Odyssey/gen_formalizer/.venv/lib/python3.13/site-packages/crewai/crew.py", line 875, in _execute_tasks
    task_output = task.execute_sync(
        agent=agent_to_use,
        context=context,
        tools=cast(List[BaseTool], tools_for_task),
    )
  File "/home/vboxuser/Documents/Math-Odyssey/gen_formalizer/.venv/lib/python3.13/site-packages/crewai/task.py", line 382, in execute_sync
    return self._execute_core(agent, context, tools)
           ~~~~~~~~~~~~~~~~~~^^^^^^^^^^^^^^^^^^^^^^^
  File "/home/vboxuser/Documents/Math-Odyssey/gen_formalizer/.venv/lib/python3.13/site-packages/crewai/task.py", line 530, in _execute_core
    raise e  # Re-raise the exception after emitting the event
    ^^^^^^^
  File "/home/vboxuser/Documents/Math-Odyssey/gen_formalizer/.venv/lib/python3.13/site-packages/crewai/task.py", line 446, in _execute_core
    result = agent.execute_task(
        task=self,
        context=context,
        tools=tools,
    )
  File "/home/vboxuser/Documents/Math-Odyssey/gen_formalizer/.venv/lib/python3.13/site-packages/crewai/agent.py", line 475, in execute_task
    raise e
  File "/home/vboxuser/Documents/Math-Odyssey/gen_formalizer/.venv/lib/python3.13/site-packages/crewai/agent.py", line 451, in execute_task
    result = self._execute_without_timeout(task_prompt, task)
  File "/home/vboxuser/Documents/Math-Odyssey/gen_formalizer/.venv/lib/python3.13/site-packages/crewai/agent.py", line 547, in _execute_without_timeout
    return self.agent_executor.invoke(
           ~~~~~~~~~~~~~~~~~~~~~~~~~~^
        {
        ^
    ...<4 lines>...
        }
        ^
    )["output"]
    ^
  File "/home/vboxuser/Documents/Math-Odyssey/gen_formalizer/.venv/lib/python3.13/site-packages/crewai/agents/crew_agent_executor.py", line 114, in invoke
    formatted_answer = self._invoke_loop()
  File "/home/vboxuser/Documents/Math-Odyssey/gen_formalizer/.venv/lib/python3.13/site-packages/crewai/agents/crew_agent_executor.py", line 208, in _invoke_loop
    raise e
  File "/home/vboxuser/Documents/Math-Odyssey/gen_formalizer/.venv/lib/python3.13/site-packages/crewai/agents/crew_agent_executor.py", line 154, in _invoke_loop
    answer = get_llm_response(
        llm=self.llm,
    ...<3 lines>...
        from_task=self.task
    )
  File "/home/vboxuser/Documents/Math-Odyssey/gen_formalizer/.venv/lib/python3.13/site-packages/crewai/utilities/agent_utils.py", line 160, in get_llm_response
    raise e
  File "/home/vboxuser/Documents/Math-Odyssey/gen_formalizer/.venv/lib/python3.13/site-packages/crewai/utilities/agent_utils.py", line 153, in get_llm_response
    answer = llm.call(
        messages,
    ...<2 lines>...
        from_agent=from_agent,
    )
  File "/home/vboxuser/Documents/Math-Odyssey/gen_formalizer/.venv/lib/python3.13/site-packages/crewai/llm.py", line 1030, in call
    return self._handle_non_streaming_response(
           ~~~~~~~~~~~~~~~~~~~~~~~~~~~~~~~~~~~^
        params, callbacks, available_functions, from_task, from_agent
        ^^^^^^^^^^^^^^^^^^^^^^^^^^^^^^^^^^^^^^^^^^^^^^^^^^^^^^^^^^^^^
    )
    ^
  File "/home/vboxuser/Documents/Math-Odyssey/gen_formalizer/.venv/lib/python3.13/site-packages/crewai/llm.py", line 813, in _handle_non_streaming_response
    response = litellm.completion(**params)
  File "/home/vboxuser/Documents/Math-Odyssey/gen_formalizer/.venv/lib/python3.13/site-packages/litellm/utils.py", line 1330, in wrapper
    raise e
  File "/home/vboxuser/Documents/Math-Odyssey/gen_formalizer/.venv/lib/python3.13/site-packages/litellm/utils.py", line 1205, in wrapper
    result = original_function(*args, **kwargs)
  File "/home/vboxuser/Documents/Math-Odyssey/gen_formalizer/.venv/lib/python3.13/site-packages/litellm/main.py", line 3427, in completion
    raise exception_type(
          ~~~~~~~~~~~~~~^
        model=model,
        ^^^^^^^^^^^^
    ...<3 lines>...
        extra_kwargs=kwargs,
        ^^^^^^^^^^^^^^^^^^^^
    )
    ^
  File "/home/vboxuser/Documents/Math-Odyssey/gen_formalizer/.venv/lib/python3.13/site-packages/litellm/litellm_core_utils/exception_mapping_utils.py", line 2301, in exception_type
    raise e
  File "/home/vboxuser/Documents/Math-Odyssey/gen_formalizer/.venv/lib/python3.13/site-packages/litellm/litellm_core_utils/exception_mapping_utils.py", line 1284, in exception_type
    raise litellm.InternalServerError(
    ...<4 lines>...
    )
litellm.exceptions.InternalServerError: litellm.InternalServerError: litellm.InternalServerError: VertexAIException - {
  "error": {
    "code": 503,
    "message": "The model is overloaded. Please try again later.",
    "status": "UNAVAILABLE"
  }
}


During handling of the above exception, another exception occurred:

Traceback (most recent call last):
  File "/home/vboxuser/Documents/Math-Odyssey/gen_formalizer/.venv/bin/run_crew", line 10, in <module>
    sys.exit(run(sys.argv[1], sys.argv[2]))
             ~~~^^^^^^^^^^^^^^^^^^^^^^^^^^
  File "/home/vboxuser/Documents/Math-Odyssey/gen_formalizer/src/gen_formalizer/main.py", line 37, in run
    raise Exception(f"An error occurred while running the crew: {e}")
Exception: An error occurred while running the crew: litellm.InternalServerError: litellm.InternalServerError: VertexAIException - {
  "error": {
    "code": 503,
    "message": "The model is overloaded. Please try again later.",
    "status": "UNAVAILABLE"
  }
}

An error occurred while running the crew: Command '['uv', 'run', 'run_crew', 'Given that the vertices of triangle $\\triangle OAB$ are $O(0,0)$, $A(4,4\\sqrt{3})$, and $B(8,0)$, with the incenter denoted as $I$, let $\\Gamma$ be a circle passing through points $A$ and $B$, intersecting circle $\\odot I$ at points $P$ and $Q$. If the tangents drawn through points $P$ and $Q$ are perpendicular, then the radius of circle $\\Gamma$ is \\_\\_\\_\\_\\_.\n\n\\end{problem}\n\\noindent', '$2 \\sqrt{7}$\\\\\n\\noindent']' returned non-zero exit status 1.
Usage: crewai run [OPTIONS] QUESTION ANSWER
Try 'crewai run --help' for help.

Error: No such option: -4
Usage: crewai run [OPTIONS] QUESTION ANSWER
Try 'crewai run --help' for help.

Error: No such option: -0
wrong: 20
correct: 80
\n
Traceback (most recent call last):
  File "/home/vboxuser/Documents/Math-Odyssey/gen_formalizer/.venv/lib/python3.13/site-packages/litellm/llms/vertex_ai/gemini/vertex_and_google_ai_studio_gemini.py", line 1890, in completion
    response = client.post(url=url, headers=headers, json=data)  # type: ignore
  File "/home/vboxuser/Documents/Math-Odyssey/gen_formalizer/.venv/lib/python3.13/site-packages/litellm/llms/custom_httpx/http_handler.py", line 780, in post
    raise e
  File "/home/vboxuser/Documents/Math-Odyssey/gen_formalizer/.venv/lib/python3.13/site-packages/litellm/llms/custom_httpx/http_handler.py", line 762, in post
    response.raise_for_status()
    ~~~~~~~~~~~~~~~~~~~~~~~~~^^
  File "/home/vboxuser/Documents/Math-Odyssey/gen_formalizer/.venv/lib/python3.13/site-packages/httpx/_models.py", line 829, in raise_for_status
    raise HTTPStatusError(message, request=request, response=self)
httpx.HTTPStatusError: Server error '503 Service Unavailable' for url 'https://generativelanguage.googleapis.com/v1beta/models/gemini-2.5-flash:generateContent?key=AIzaSyDoL-8LOr6PUL1KLHCAQsSWl9uJ1PsMD7o'
For more information check: https://developer.mozilla.org/en-US/docs/Web/HTTP/Status/503

During handling of the above exception, another exception occurred:

Traceback (most recent call last):
  File "/home/vboxuser/Documents/Math-Odyssey/gen_formalizer/.venv/lib/python3.13/site-packages/litellm/main.py", line 2606, in completion
    response = vertex_chat_completion.completion(  # type: ignore
        model=model,
    ...<17 lines>...
        extra_headers=extra_headers,
    )
  File "/home/vboxuser/Documents/Math-Odyssey/gen_formalizer/.venv/lib/python3.13/site-packages/litellm/llms/vertex_ai/gemini/vertex_and_google_ai_studio_gemini.py", line 1894, in completion
    raise VertexAIError(
    ...<3 lines>...
    )
litellm.llms.vertex_ai.common_utils.VertexAIError: {
  "error": {
    "code": 503,
    "message": "The model is overloaded. Please try again later.",
    "status": "UNAVAILABLE"
  }
}


During handling of the above exception, another exception occurred:

Traceback (most recent call last):
  File "/home/vboxuser/Documents/Math-Odyssey/gen_formalizer/src/gen_formalizer/main.py", line 29, in run
    result = GenFormalizer().crew().kickoff(inputs=inputs)
  File "/home/vboxuser/Documents/Math-Odyssey/gen_formalizer/.venv/lib/python3.13/site-packages/crewai/crew.py", line 661, in kickoff
    result = self._run_sequential_process()
  File "/home/vboxuser/Documents/Math-Odyssey/gen_formalizer/.venv/lib/python3.13/site-packages/crewai/crew.py", line 772, in _run_sequential_process
    return self._execute_tasks(self.tasks)
           ~~~~~~~~~~~~~~~~~~~^^^^^^^^^^^^
  File "/home/vboxuser/Documents/Math-Odyssey/gen_formalizer/.venv/lib/python3.13/site-packages/crewai/crew.py", line 875, in _execute_tasks
    task_output = task.execute_sync(
        agent=agent_to_use,
        context=context,
        tools=cast(List[BaseTool], tools_for_task),
    )
  File "/home/vboxuser/Documents/Math-Odyssey/gen_formalizer/.venv/lib/python3.13/site-packages/crewai/task.py", line 382, in execute_sync
    return self._execute_core(agent, context, tools)
           ~~~~~~~~~~~~~~~~~~^^^^^^^^^^^^^^^^^^^^^^^
  File "/home/vboxuser/Documents/Math-Odyssey/gen_formalizer/.venv/lib/python3.13/site-packages/crewai/task.py", line 530, in _execute_core
    raise e  # Re-raise the exception after emitting the event
    ^^^^^^^
  File "/home/vboxuser/Documents/Math-Odyssey/gen_formalizer/.venv/lib/python3.13/site-packages/crewai/task.py", line 446, in _execute_core
    result = agent.execute_task(
        task=self,
        context=context,
        tools=tools,
    )
  File "/home/vboxuser/Documents/Math-Odyssey/gen_formalizer/.venv/lib/python3.13/site-packages/crewai/agent.py", line 475, in execute_task
    raise e
  File "/home/vboxuser/Documents/Math-Odyssey/gen_formalizer/.venv/lib/python3.13/site-packages/crewai/agent.py", line 451, in execute_task
    result = self._execute_without_timeout(task_prompt, task)
  File "/home/vboxuser/Documents/Math-Odyssey/gen_formalizer/.venv/lib/python3.13/site-packages/crewai/agent.py", line 547, in _execute_without_timeout
    return self.agent_executor.invoke(
           ~~~~~~~~~~~~~~~~~~~~~~~~~~^
        {
        ^
    ...<4 lines>...
        }
        ^
    )["output"]
    ^
  File "/home/vboxuser/Documents/Math-Odyssey/gen_formalizer/.venv/lib/python3.13/site-packages/crewai/agents/crew_agent_executor.py", line 114, in invoke
    formatted_answer = self._invoke_loop()
  File "/home/vboxuser/Documents/Math-Odyssey/gen_formalizer/.venv/lib/python3.13/site-packages/crewai/agents/crew_agent_executor.py", line 208, in _invoke_loop
    raise e
  File "/home/vboxuser/Documents/Math-Odyssey/gen_formalizer/.venv/lib/python3.13/site-packages/crewai/agents/crew_agent_executor.py", line 154, in _invoke_loop
    answer = get_llm_response(
        llm=self.llm,
    ...<3 lines>...
        from_task=self.task
    )
  File "/home/vboxuser/Documents/Math-Odyssey/gen_formalizer/.venv/lib/python3.13/site-packages/crewai/utilities/agent_utils.py", line 160, in get_llm_response
    raise e
  File "/home/vboxuser/Documents/Math-Odyssey/gen_formalizer/.venv/lib/python3.13/site-packages/crewai/utilities/agent_utils.py", line 153, in get_llm_response
    answer = llm.call(
        messages,
    ...<2 lines>...
        from_agent=from_agent,
    )
  File "/home/vboxuser/Documents/Math-Odyssey/gen_formalizer/.venv/lib/python3.13/site-packages/crewai/llm.py", line 1030, in call
    return self._handle_non_streaming_response(
           ~~~~~~~~~~~~~~~~~~~~~~~~~~~~~~~~~~~^
        params, callbacks, available_functions, from_task, from_agent
        ^^^^^^^^^^^^^^^^^^^^^^^^^^^^^^^^^^^^^^^^^^^^^^^^^^^^^^^^^^^^^
    )
    ^
  File "/home/vboxuser/Documents/Math-Odyssey/gen_formalizer/.venv/lib/python3.13/site-packages/crewai/llm.py", line 813, in _handle_non_streaming_response
    response = litellm.completion(**params)
  File "/home/vboxuser/Documents/Math-Odyssey/gen_formalizer/.venv/lib/python3.13/site-packages/litellm/utils.py", line 1330, in wrapper
    raise e
  File "/home/vboxuser/Documents/Math-Odyssey/gen_formalizer/.venv/lib/python3.13/site-packages/litellm/utils.py", line 1205, in wrapper
    result = original_function(*args, **kwargs)
  File "/home/vboxuser/Documents/Math-Odyssey/gen_formalizer/.venv/lib/python3.13/site-packages/litellm/main.py", line 3427, in completion
    raise exception_type(
          ~~~~~~~~~~~~~~^
        model=model,
        ^^^^^^^^^^^^
    ...<3 lines>...
        extra_kwargs=kwargs,
        ^^^^^^^^^^^^^^^^^^^^
    )
    ^
  File "/home/vboxuser/Documents/Math-Odyssey/gen_formalizer/.venv/lib/python3.13/site-packages/litellm/litellm_core_utils/exception_mapping_utils.py", line 2301, in exception_type
    raise e
  File "/home/vboxuser/Documents/Math-Odyssey/gen_formalizer/.venv/lib/python3.13/site-packages/litellm/litellm_core_utils/exception_mapping_utils.py", line 1284, in exception_type
    raise litellm.InternalServerError(
    ...<4 lines>...
    )
litellm.exceptions.InternalServerError: litellm.InternalServerError: litellm.InternalServerError: VertexAIException - {
  "error": {
    "code": 503,
    "message": "The model is overloaded. Please try again later.",
    "status": "UNAVAILABLE"
  }
}


During handling of the above exception, another exception occurred:

Traceback (most recent call last):
  File "/home/vboxuser/Documents/Math-Odyssey/gen_formalizer/.venv/bin/run_crew", line 10, in <module>
    sys.exit(run(sys.argv[1], sys.argv[2]))
             ~~~^^^^^^^^^^^^^^^^^^^^^^^^^^
  File "/home/vboxuser/Documents/Math-Odyssey/gen_formalizer/src/gen_formalizer/main.py", line 37, in run
    raise Exception(f"An error occurred while running the crew: {e}")
Exception: An error occurred while running the crew: litellm.InternalServerError: litellm.InternalServerError: VertexAIException - {
  "error": {
    "code": 503,
    "message": "The model is overloaded. Please try again later.",
    "status": "UNAVAILABLE"
  }
}

An error occurred while running the crew: Command '['uv', 'run', 'run_crew', 'For a positive integer $n$, which can be uniquely expressed as the sum of the squares of 5 or fewer positive integers (where two expressions with different summation orders are considered the same, such as $3^2+4^2$ and $4^2+3^2$ are considered the same expression of 25), then the sum of all the $n$ that satisfy the conditions is \\underline{\\hspace{2cm}}.\n\t\n\t\n\\end{problem}\n\\noindent', '34\\\\\n\\noindent']' returned non-zero exit status 1.
Usage: crewai run [OPTIONS] QUESTION ANSWER
Try 'crewai run --help' for help.

Error: No such option: -2
wrong: 17
correct: 83
\n
Usage: crewai run [OPTIONS] QUESTION ANSWER
Try 'crewai run --help' for help.

Error: No such option: -1
Traceback (most recent call last):
  File "/home/vboxuser/Documents/Math-Odyssey/gen_formalizer/.venv/lib/python3.13/site-packages/litellm/llms/vertex_ai/gemini/vertex_and_google_ai_studio_gemini.py", line 1890, in completion
    response = client.post(url=url, headers=headers, json=data)  # type: ignore
  File "/home/vboxuser/Documents/Math-Odyssey/gen_formalizer/.venv/lib/python3.13/site-packages/litellm/llms/custom_httpx/http_handler.py", line 780, in post
    raise e
  File "/home/vboxuser/Documents/Math-Odyssey/gen_formalizer/.venv/lib/python3.13/site-packages/litellm/llms/custom_httpx/http_handler.py", line 762, in post
    response.raise_for_status()
    ~~~~~~~~~~~~~~~~~~~~~~~~~^^
  File "/home/vboxuser/Documents/Math-Odyssey/gen_formalizer/.venv/lib/python3.13/site-packages/httpx/_models.py", line 829, in raise_for_status
    raise HTTPStatusError(message, request=request, response=self)
httpx.HTTPStatusError: Server error '503 Service Unavailable' for url 'https://generativelanguage.googleapis.com/v1beta/models/gemini-2.5-flash:generateContent?key=AIzaSyDoL-8LOr6PUL1KLHCAQsSWl9uJ1PsMD7o'
For more information check: https://developer.mozilla.org/en-US/docs/Web/HTTP/Status/503

During handling of the above exception, another exception occurred:

Traceback (most recent call last):
  File "/home/vboxuser/Documents/Math-Odyssey/gen_formalizer/.venv/lib/python3.13/site-packages/litellm/main.py", line 2606, in completion
    response = vertex_chat_completion.completion(  # type: ignore
        model=model,
    ...<17 lines>...
        extra_headers=extra_headers,
    )
  File "/home/vboxuser/Documents/Math-Odyssey/gen_formalizer/.venv/lib/python3.13/site-packages/litellm/llms/vertex_ai/gemini/vertex_and_google_ai_studio_gemini.py", line 1894, in completion
    raise VertexAIError(
    ...<3 lines>...
    )
litellm.llms.vertex_ai.common_utils.VertexAIError: {
  "error": {
    "code": 503,
    "message": "The model is overloaded. Please try again later.",
    "status": "UNAVAILABLE"
  }
}


During handling of the above exception, another exception occurred:

Traceback (most recent call last):
  File "/home/vboxuser/Documents/Math-Odyssey/gen_formalizer/src/gen_formalizer/main.py", line 29, in run
    result = GenFormalizer().crew().kickoff(inputs=inputs)
  File "/home/vboxuser/Documents/Math-Odyssey/gen_formalizer/.venv/lib/python3.13/site-packages/crewai/crew.py", line 661, in kickoff
    result = self._run_sequential_process()
  File "/home/vboxuser/Documents/Math-Odyssey/gen_formalizer/.venv/lib/python3.13/site-packages/crewai/crew.py", line 772, in _run_sequential_process
    return self._execute_tasks(self.tasks)
           ~~~~~~~~~~~~~~~~~~~^^^^^^^^^^^^
  File "/home/vboxuser/Documents/Math-Odyssey/gen_formalizer/.venv/lib/python3.13/site-packages/crewai/crew.py", line 875, in _execute_tasks
    task_output = task.execute_sync(
        agent=agent_to_use,
        context=context,
        tools=cast(List[BaseTool], tools_for_task),
    )
  File "/home/vboxuser/Documents/Math-Odyssey/gen_formalizer/.venv/lib/python3.13/site-packages/crewai/task.py", line 382, in execute_sync
    return self._execute_core(agent, context, tools)
           ~~~~~~~~~~~~~~~~~~^^^^^^^^^^^^^^^^^^^^^^^
  File "/home/vboxuser/Documents/Math-Odyssey/gen_formalizer/.venv/lib/python3.13/site-packages/crewai/task.py", line 530, in _execute_core
    raise e  # Re-raise the exception after emitting the event
    ^^^^^^^
  File "/home/vboxuser/Documents/Math-Odyssey/gen_formalizer/.venv/lib/python3.13/site-packages/crewai/task.py", line 446, in _execute_core
    result = agent.execute_task(
        task=self,
        context=context,
        tools=tools,
    )
  File "/home/vboxuser/Documents/Math-Odyssey/gen_formalizer/.venv/lib/python3.13/site-packages/crewai/agent.py", line 475, in execute_task
    raise e
  File "/home/vboxuser/Documents/Math-Odyssey/gen_formalizer/.venv/lib/python3.13/site-packages/crewai/agent.py", line 451, in execute_task
    result = self._execute_without_timeout(task_prompt, task)
  File "/home/vboxuser/Documents/Math-Odyssey/gen_formalizer/.venv/lib/python3.13/site-packages/crewai/agent.py", line 547, in _execute_without_timeout
    return self.agent_executor.invoke(
           ~~~~~~~~~~~~~~~~~~~~~~~~~~^
        {
        ^
    ...<4 lines>...
        }
        ^
    )["output"]
    ^
  File "/home/vboxuser/Documents/Math-Odyssey/gen_formalizer/.venv/lib/python3.13/site-packages/crewai/agents/crew_agent_executor.py", line 114, in invoke
    formatted_answer = self._invoke_loop()
  File "/home/vboxuser/Documents/Math-Odyssey/gen_formalizer/.venv/lib/python3.13/site-packages/crewai/agents/crew_agent_executor.py", line 208, in _invoke_loop
    raise e
  File "/home/vboxuser/Documents/Math-Odyssey/gen_formalizer/.venv/lib/python3.13/site-packages/crewai/agents/crew_agent_executor.py", line 154, in _invoke_loop
    answer = get_llm_response(
        llm=self.llm,
    ...<3 lines>...
        from_task=self.task
    )
  File "/home/vboxuser/Documents/Math-Odyssey/gen_formalizer/.venv/lib/python3.13/site-packages/crewai/utilities/agent_utils.py", line 160, in get_llm_response
    raise e
  File "/home/vboxuser/Documents/Math-Odyssey/gen_formalizer/.venv/lib/python3.13/site-packages/crewai/utilities/agent_utils.py", line 153, in get_llm_response
    answer = llm.call(
        messages,
    ...<2 lines>...
        from_agent=from_agent,
    )
  File "/home/vboxuser/Documents/Math-Odyssey/gen_formalizer/.venv/lib/python3.13/site-packages/crewai/llm.py", line 1030, in call
    return self._handle_non_streaming_response(
           ~~~~~~~~~~~~~~~~~~~~~~~~~~~~~~~~~~~^
        params, callbacks, available_functions, from_task, from_agent
        ^^^^^^^^^^^^^^^^^^^^^^^^^^^^^^^^^^^^^^^^^^^^^^^^^^^^^^^^^^^^^
    )
    ^
  File "/home/vboxuser/Documents/Math-Odyssey/gen_formalizer/.venv/lib/python3.13/site-packages/crewai/llm.py", line 813, in _handle_non_streaming_response
    response = litellm.completion(**params)
  File "/home/vboxuser/Documents/Math-Odyssey/gen_formalizer/.venv/lib/python3.13/site-packages/litellm/utils.py", line 1330, in wrapper
    raise e
  File "/home/vboxuser/Documents/Math-Odyssey/gen_formalizer/.venv/lib/python3.13/site-packages/litellm/utils.py", line 1205, in wrapper
    result = original_function(*args, **kwargs)
  File "/home/vboxuser/Documents/Math-Odyssey/gen_formalizer/.venv/lib/python3.13/site-packages/litellm/main.py", line 3427, in completion
    raise exception_type(
          ~~~~~~~~~~~~~~^
        model=model,
        ^^^^^^^^^^^^
    ...<3 lines>...
        extra_kwargs=kwargs,
        ^^^^^^^^^^^^^^^^^^^^
    )
    ^
  File "/home/vboxuser/Documents/Math-Odyssey/gen_formalizer/.venv/lib/python3.13/site-packages/litellm/litellm_core_utils/exception_mapping_utils.py", line 2301, in exception_type
    raise e
  File "/home/vboxuser/Documents/Math-Odyssey/gen_formalizer/.venv/lib/python3.13/site-packages/litellm/litellm_core_utils/exception_mapping_utils.py", line 1284, in exception_type
    raise litellm.InternalServerError(
    ...<4 lines>...
    )
litellm.exceptions.InternalServerError: litellm.InternalServerError: litellm.InternalServerError: VertexAIException - {
  "error": {
    "code": 503,
    "message": "The model is overloaded. Please try again later.",
    "status": "UNAVAILABLE"
  }
}


During handling of the above exception, another exception occurred:

Traceback (most recent call last):
  File "/home/vboxuser/Documents/Math-Odyssey/gen_formalizer/.venv/bin/run_crew", line 10, in <module>
    sys.exit(run(sys.argv[1], sys.argv[2]))
             ~~~^^^^^^^^^^^^^^^^^^^^^^^^^^
  File "/home/vboxuser/Documents/Math-Odyssey/gen_formalizer/src/gen_formalizer/main.py", line 37, in run
    raise Exception(f"An error occurred while running the crew: {e}")
Exception: An error occurred while running the crew: litellm.InternalServerError: litellm.InternalServerError: VertexAIException - {
  "error": {
    "code": 503,
    "message": "The model is overloaded. Please try again later.",
    "status": "UNAVAILABLE"
  }
}

An error occurred while running the crew: Command '['uv', 'run', 'run_crew', 'A rook piece moves through  each square of a $2023\\times 2023 $ grid paper once, each time moving only one square (i.e., from the current square to an adjacent square). If the squares are numbered from 1 to $n^2$ according to the order in which the rook piece reaches them, let M denote the maximum difference in numbers between adjacent squares. Then the minimum possible value of $M$ is?\n\\end{problem}\n\\noindent', '4045\\\\\n\\noindent']' returned non-zero exit status 1.
Traceback (most recent call last):
  File "/home/vboxuser/Documents/Math-Odyssey/gen_formalizer/.venv/lib/python3.13/site-packages/litellm/llms/vertex_ai/gemini/vertex_and_google_ai_studio_gemini.py", line 1890, in completion
    response = client.post(url=url, headers=headers, json=data)  # type: ignore
  File "/home/vboxuser/Documents/Math-Odyssey/gen_formalizer/.venv/lib/python3.13/site-packages/litellm/llms/custom_httpx/http_handler.py", line 780, in post
    raise e
  File "/home/vboxuser/Documents/Math-Odyssey/gen_formalizer/.venv/lib/python3.13/site-packages/litellm/llms/custom_httpx/http_handler.py", line 762, in post
    response.raise_for_status()
    ~~~~~~~~~~~~~~~~~~~~~~~~~^^
  File "/home/vboxuser/Documents/Math-Odyssey/gen_formalizer/.venv/lib/python3.13/site-packages/httpx/_models.py", line 829, in raise_for_status
    raise HTTPStatusError(message, request=request, response=self)
httpx.HTTPStatusError: Server error '503 Service Unavailable' for url 'https://generativelanguage.googleapis.com/v1beta/models/gemini-2.5-flash:generateContent?key=AIzaSyDoL-8LOr6PUL1KLHCAQsSWl9uJ1PsMD7o'
For more information check: https://developer.mozilla.org/en-US/docs/Web/HTTP/Status/503

During handling of the above exception, another exception occurred:

Traceback (most recent call last):
  File "/home/vboxuser/Documents/Math-Odyssey/gen_formalizer/.venv/lib/python3.13/site-packages/litellm/main.py", line 2606, in completion
    response = vertex_chat_completion.completion(  # type: ignore
        model=model,
    ...<17 lines>...
        extra_headers=extra_headers,
    )
  File "/home/vboxuser/Documents/Math-Odyssey/gen_formalizer/.venv/lib/python3.13/site-packages/litellm/llms/vertex_ai/gemini/vertex_and_google_ai_studio_gemini.py", line 1894, in completion
    raise VertexAIError(
    ...<3 lines>...
    )
litellm.llms.vertex_ai.common_utils.VertexAIError: {
  "error": {
    "code": 503,
    "message": "The model is overloaded. Please try again later.",
    "status": "UNAVAILABLE"
  }
}


During handling of the above exception, another exception occurred:

Traceback (most recent call last):
  File "/home/vboxuser/Documents/Math-Odyssey/gen_formalizer/src/gen_formalizer/main.py", line 29, in run
    result = GenFormalizer().crew().kickoff(inputs=inputs)
  File "/home/vboxuser/Documents/Math-Odyssey/gen_formalizer/.venv/lib/python3.13/site-packages/crewai/crew.py", line 661, in kickoff
    result = self._run_sequential_process()
  File "/home/vboxuser/Documents/Math-Odyssey/gen_formalizer/.venv/lib/python3.13/site-packages/crewai/crew.py", line 772, in _run_sequential_process
    return self._execute_tasks(self.tasks)
           ~~~~~~~~~~~~~~~~~~~^^^^^^^^^^^^
  File "/home/vboxuser/Documents/Math-Odyssey/gen_formalizer/.venv/lib/python3.13/site-packages/crewai/crew.py", line 875, in _execute_tasks
    task_output = task.execute_sync(
        agent=agent_to_use,
        context=context,
        tools=cast(List[BaseTool], tools_for_task),
    )
  File "/home/vboxuser/Documents/Math-Odyssey/gen_formalizer/.venv/lib/python3.13/site-packages/crewai/task.py", line 382, in execute_sync
    return self._execute_core(agent, context, tools)
           ~~~~~~~~~~~~~~~~~~^^^^^^^^^^^^^^^^^^^^^^^
  File "/home/vboxuser/Documents/Math-Odyssey/gen_formalizer/.venv/lib/python3.13/site-packages/crewai/task.py", line 530, in _execute_core
    raise e  # Re-raise the exception after emitting the event
    ^^^^^^^
  File "/home/vboxuser/Documents/Math-Odyssey/gen_formalizer/.venv/lib/python3.13/site-packages/crewai/task.py", line 446, in _execute_core
    result = agent.execute_task(
        task=self,
        context=context,
        tools=tools,
    )
  File "/home/vboxuser/Documents/Math-Odyssey/gen_formalizer/.venv/lib/python3.13/site-packages/crewai/agent.py", line 475, in execute_task
    raise e
  File "/home/vboxuser/Documents/Math-Odyssey/gen_formalizer/.venv/lib/python3.13/site-packages/crewai/agent.py", line 451, in execute_task
    result = self._execute_without_timeout(task_prompt, task)
  File "/home/vboxuser/Documents/Math-Odyssey/gen_formalizer/.venv/lib/python3.13/site-packages/crewai/agent.py", line 547, in _execute_without_timeout
    return self.agent_executor.invoke(
           ~~~~~~~~~~~~~~~~~~~~~~~~~~^
        {
        ^
    ...<4 lines>...
        }
        ^
    )["output"]
    ^
  File "/home/vboxuser/Documents/Math-Odyssey/gen_formalizer/.venv/lib/python3.13/site-packages/crewai/agents/crew_agent_executor.py", line 114, in invoke
    formatted_answer = self._invoke_loop()
  File "/home/vboxuser/Documents/Math-Odyssey/gen_formalizer/.venv/lib/python3.13/site-packages/crewai/agents/crew_agent_executor.py", line 208, in _invoke_loop
    raise e
  File "/home/vboxuser/Documents/Math-Odyssey/gen_formalizer/.venv/lib/python3.13/site-packages/crewai/agents/crew_agent_executor.py", line 154, in _invoke_loop
    answer = get_llm_response(
        llm=self.llm,
    ...<3 lines>...
        from_task=self.task
    )
  File "/home/vboxuser/Documents/Math-Odyssey/gen_formalizer/.venv/lib/python3.13/site-packages/crewai/utilities/agent_utils.py", line 160, in get_llm_response
    raise e
  File "/home/vboxuser/Documents/Math-Odyssey/gen_formalizer/.venv/lib/python3.13/site-packages/crewai/utilities/agent_utils.py", line 153, in get_llm_response
    answer = llm.call(
        messages,
    ...<2 lines>...
        from_agent=from_agent,
    )
  File "/home/vboxuser/Documents/Math-Odyssey/gen_formalizer/.venv/lib/python3.13/site-packages/crewai/llm.py", line 1030, in call
    return self._handle_non_streaming_response(
           ~~~~~~~~~~~~~~~~~~~~~~~~~~~~~~~~~~~^
        params, callbacks, available_functions, from_task, from_agent
        ^^^^^^^^^^^^^^^^^^^^^^^^^^^^^^^^^^^^^^^^^^^^^^^^^^^^^^^^^^^^^
    )
    ^
  File "/home/vboxuser/Documents/Math-Odyssey/gen_formalizer/.venv/lib/python3.13/site-packages/crewai/llm.py", line 813, in _handle_non_streaming_response
    response = litellm.completion(**params)
  File "/home/vboxuser/Documents/Math-Odyssey/gen_formalizer/.venv/lib/python3.13/site-packages/litellm/utils.py", line 1330, in wrapper
    raise e
  File "/home/vboxuser/Documents/Math-Odyssey/gen_formalizer/.venv/lib/python3.13/site-packages/litellm/utils.py", line 1205, in wrapper
    result = original_function(*args, **kwargs)
  File "/home/vboxuser/Documents/Math-Odyssey/gen_formalizer/.venv/lib/python3.13/site-packages/litellm/main.py", line 3427, in completion
    raise exception_type(
          ~~~~~~~~~~~~~~^
        model=model,
        ^^^^^^^^^^^^
    ...<3 lines>...
        extra_kwargs=kwargs,
        ^^^^^^^^^^^^^^^^^^^^
    )
    ^
  File "/home/vboxuser/Documents/Math-Odyssey/gen_formalizer/.venv/lib/python3.13/site-packages/litellm/litellm_core_utils/exception_mapping_utils.py", line 2301, in exception_type
    raise e
  File "/home/vboxuser/Documents/Math-Odyssey/gen_formalizer/.venv/lib/python3.13/site-packages/litellm/litellm_core_utils/exception_mapping_utils.py", line 1284, in exception_type
    raise litellm.InternalServerError(
    ...<4 lines>...
    )
litellm.exceptions.InternalServerError: litellm.InternalServerError: litellm.InternalServerError: VertexAIException - {
  "error": {
    "code": 503,
    "message": "The model is overloaded. Please try again later.",
    "status": "UNAVAILABLE"
  }
}


During handling of the above exception, another exception occurred:

Traceback (most recent call last):
  File "/home/vboxuser/Documents/Math-Odyssey/gen_formalizer/.venv/bin/run_crew", line 10, in <module>
    sys.exit(run(sys.argv[1], sys.argv[2]))
             ~~~^^^^^^^^^^^^^^^^^^^^^^^^^^
  File "/home/vboxuser/Documents/Math-Odyssey/gen_formalizer/src/gen_formalizer/main.py", line 37, in run
    raise Exception(f"An error occurred while running the crew: {e}")
Exception: An error occurred while running the crew: litellm.InternalServerError: litellm.InternalServerError: VertexAIException - {
  "error": {
    "code": 503,
    "message": "The model is overloaded. Please try again later.",
    "status": "UNAVAILABLE"
  }
}

An error occurred while running the crew: Command '['uv', 'run', 'run_crew', 'On a plane, there are 2019 points. Drawing circles passing through these points, a drawing method is called "$k$-good" if and only if drawing $k$ circles divides the plane into several closed shapes, and there is no closed shape containing two points. Then, find the minimum value of $k$ , it ensures that no matter how these 2019 points are arranged, there always exists a $k$-good drawing method.\n\\end{problem}\n\\noindent', '1010\\\\\n\\noindent']' returned non-zero exit status 1.
Usage: crewai run [OPTIONS] QUESTION ANSWER
Try 'crewai run --help' for help.

Error: No such option: -4
Traceback (most recent call last):
  File "/home/vboxuser/Documents/Math-Odyssey/gen_formalizer/.venv/lib/python3.13/site-packages/litellm/llms/vertex_ai/gemini/vertex_and_google_ai_studio_gemini.py", line 1890, in completion
    response = client.post(url=url, headers=headers, json=data)  # type: ignore
  File "/home/vboxuser/Documents/Math-Odyssey/gen_formalizer/.venv/lib/python3.13/site-packages/litellm/llms/custom_httpx/http_handler.py", line 780, in post
    raise e
  File "/home/vboxuser/Documents/Math-Odyssey/gen_formalizer/.venv/lib/python3.13/site-packages/litellm/llms/custom_httpx/http_handler.py", line 762, in post
    response.raise_for_status()
    ~~~~~~~~~~~~~~~~~~~~~~~~~^^
  File "/home/vboxuser/Documents/Math-Odyssey/gen_formalizer/.venv/lib/python3.13/site-packages/httpx/_models.py", line 829, in raise_for_status
    raise HTTPStatusError(message, request=request, response=self)
httpx.HTTPStatusError: Server error '503 Service Unavailable' for url 'https://generativelanguage.googleapis.com/v1beta/models/gemini-2.5-flash:generateContent?key=AIzaSyDoL-8LOr6PUL1KLHCAQsSWl9uJ1PsMD7o'
For more information check: https://developer.mozilla.org/en-US/docs/Web/HTTP/Status/503

During handling of the above exception, another exception occurred:

Traceback (most recent call last):
  File "/home/vboxuser/Documents/Math-Odyssey/gen_formalizer/.venv/lib/python3.13/site-packages/litellm/main.py", line 2606, in completion
    response = vertex_chat_completion.completion(  # type: ignore
        model=model,
    ...<17 lines>...
        extra_headers=extra_headers,
    )
  File "/home/vboxuser/Documents/Math-Odyssey/gen_formalizer/.venv/lib/python3.13/site-packages/litellm/llms/vertex_ai/gemini/vertex_and_google_ai_studio_gemini.py", line 1894, in completion
    raise VertexAIError(
    ...<3 lines>...
    )
litellm.llms.vertex_ai.common_utils.VertexAIError: {
  "error": {
    "code": 503,
    "message": "The model is overloaded. Please try again later.",
    "status": "UNAVAILABLE"
  }
}


During handling of the above exception, another exception occurred:

Traceback (most recent call last):
  File "/home/vboxuser/Documents/Math-Odyssey/gen_formalizer/src/gen_formalizer/main.py", line 29, in run
    result = GenFormalizer().crew().kickoff(inputs=inputs)
  File "/home/vboxuser/Documents/Math-Odyssey/gen_formalizer/.venv/lib/python3.13/site-packages/crewai/crew.py", line 661, in kickoff
    result = self._run_sequential_process()
  File "/home/vboxuser/Documents/Math-Odyssey/gen_formalizer/.venv/lib/python3.13/site-packages/crewai/crew.py", line 772, in _run_sequential_process
    return self._execute_tasks(self.tasks)
           ~~~~~~~~~~~~~~~~~~~^^^^^^^^^^^^
  File "/home/vboxuser/Documents/Math-Odyssey/gen_formalizer/.venv/lib/python3.13/site-packages/crewai/crew.py", line 875, in _execute_tasks
    task_output = task.execute_sync(
        agent=agent_to_use,
        context=context,
        tools=cast(List[BaseTool], tools_for_task),
    )
  File "/home/vboxuser/Documents/Math-Odyssey/gen_formalizer/.venv/lib/python3.13/site-packages/crewai/task.py", line 382, in execute_sync
    return self._execute_core(agent, context, tools)
           ~~~~~~~~~~~~~~~~~~^^^^^^^^^^^^^^^^^^^^^^^
  File "/home/vboxuser/Documents/Math-Odyssey/gen_formalizer/.venv/lib/python3.13/site-packages/crewai/task.py", line 530, in _execute_core
    raise e  # Re-raise the exception after emitting the event
    ^^^^^^^
  File "/home/vboxuser/Documents/Math-Odyssey/gen_formalizer/.venv/lib/python3.13/site-packages/crewai/task.py", line 446, in _execute_core
    result = agent.execute_task(
        task=self,
        context=context,
        tools=tools,
    )
  File "/home/vboxuser/Documents/Math-Odyssey/gen_formalizer/.venv/lib/python3.13/site-packages/crewai/agent.py", line 475, in execute_task
    raise e
  File "/home/vboxuser/Documents/Math-Odyssey/gen_formalizer/.venv/lib/python3.13/site-packages/crewai/agent.py", line 451, in execute_task
    result = self._execute_without_timeout(task_prompt, task)
  File "/home/vboxuser/Documents/Math-Odyssey/gen_formalizer/.venv/lib/python3.13/site-packages/crewai/agent.py", line 547, in _execute_without_timeout
    return self.agent_executor.invoke(
           ~~~~~~~~~~~~~~~~~~~~~~~~~~^
        {
        ^
    ...<4 lines>...
        }
        ^
    )["output"]
    ^
  File "/home/vboxuser/Documents/Math-Odyssey/gen_formalizer/.venv/lib/python3.13/site-packages/crewai/agents/crew_agent_executor.py", line 114, in invoke
    formatted_answer = self._invoke_loop()
  File "/home/vboxuser/Documents/Math-Odyssey/gen_formalizer/.venv/lib/python3.13/site-packages/crewai/agents/crew_agent_executor.py", line 208, in _invoke_loop
    raise e
  File "/home/vboxuser/Documents/Math-Odyssey/gen_formalizer/.venv/lib/python3.13/site-packages/crewai/agents/crew_agent_executor.py", line 154, in _invoke_loop
    answer = get_llm_response(
        llm=self.llm,
    ...<3 lines>...
        from_task=self.task
    )
  File "/home/vboxuser/Documents/Math-Odyssey/gen_formalizer/.venv/lib/python3.13/site-packages/crewai/utilities/agent_utils.py", line 160, in get_llm_response
    raise e
  File "/home/vboxuser/Documents/Math-Odyssey/gen_formalizer/.venv/lib/python3.13/site-packages/crewai/utilities/agent_utils.py", line 153, in get_llm_response
    answer = llm.call(
        messages,
    ...<2 lines>...
        from_agent=from_agent,
    )
  File "/home/vboxuser/Documents/Math-Odyssey/gen_formalizer/.venv/lib/python3.13/site-packages/crewai/llm.py", line 1030, in call
    return self._handle_non_streaming_response(
           ~~~~~~~~~~~~~~~~~~~~~~~~~~~~~~~~~~~^
        params, callbacks, available_functions, from_task, from_agent
        ^^^^^^^^^^^^^^^^^^^^^^^^^^^^^^^^^^^^^^^^^^^^^^^^^^^^^^^^^^^^^
    )
    ^
  File "/home/vboxuser/Documents/Math-Odyssey/gen_formalizer/.venv/lib/python3.13/site-packages/crewai/llm.py", line 813, in _handle_non_streaming_response
    response = litellm.completion(**params)
  File "/home/vboxuser/Documents/Math-Odyssey/gen_formalizer/.venv/lib/python3.13/site-packages/litellm/utils.py", line 1330, in wrapper
    raise e
  File "/home/vboxuser/Documents/Math-Odyssey/gen_formalizer/.venv/lib/python3.13/site-packages/litellm/utils.py", line 1205, in wrapper
    result = original_function(*args, **kwargs)
  File "/home/vboxuser/Documents/Math-Odyssey/gen_formalizer/.venv/lib/python3.13/site-packages/litellm/main.py", line 3427, in completion
    raise exception_type(
          ~~~~~~~~~~~~~~^
        model=model,
        ^^^^^^^^^^^^
    ...<3 lines>...
        extra_kwargs=kwargs,
        ^^^^^^^^^^^^^^^^^^^^
    )
    ^
  File "/home/vboxuser/Documents/Math-Odyssey/gen_formalizer/.venv/lib/python3.13/site-packages/litellm/litellm_core_utils/exception_mapping_utils.py", line 2301, in exception_type
    raise e
  File "/home/vboxuser/Documents/Math-Odyssey/gen_formalizer/.venv/lib/python3.13/site-packages/litellm/litellm_core_utils/exception_mapping_utils.py", line 1284, in exception_type
    raise litellm.InternalServerError(
    ...<4 lines>...
    )
litellm.exceptions.InternalServerError: litellm.InternalServerError: litellm.InternalServerError: VertexAIException - {
  "error": {
    "code": 503,
    "message": "The model is overloaded. Please try again later.",
    "status": "UNAVAILABLE"
  }
}


During handling of the above exception, another exception occurred:

Traceback (most recent call last):
  File "/home/vboxuser/Documents/Math-Odyssey/gen_formalizer/.venv/bin/run_crew", line 10, in <module>
    sys.exit(run(sys.argv[1], sys.argv[2]))
             ~~~^^^^^^^^^^^^^^^^^^^^^^^^^^
  File "/home/vboxuser/Documents/Math-Odyssey/gen_formalizer/src/gen_formalizer/main.py", line 37, in run
    raise Exception(f"An error occurred while running the crew: {e}")
Exception: An error occurred while running the crew: litellm.InternalServerError: litellm.InternalServerError: VertexAIException - {
  "error": {
    "code": 503,
    "message": "The model is overloaded. Please try again later.",
    "status": "UNAVAILABLE"
  }
}

An error occurred while running the crew: Command '['uv', 'run', 'run_crew', 'Given $\\triangle A B C$, where $\\angle \\mathrm{A}=41^{\\circ}, \\angle \\mathrm{B}=58^{\\circ}$, and $\\mathrm{c}=19.7 \\mathrm{~cm}$, determine the measure of side $\\mathrm{b}$.\n\\begin{align*}\n\\text{A)}\\ & \\text{not possible} &\n\\text{B)}\\ &  16.91 \\mathrm{~cm} \\\\\n\\text{C)}\\ & 0.89 \\mathrm{~cm}  &\n\\text{D)}\\ & 12.94 \\mathrm{~cm}\\\\\n\\end{align*}    \n\\end{problem}\n\\noindent', 'B\\\\\n\\noindent']' returned non-zero exit status 1.
wrong: 25
correct: 75
\n
Traceback (most recent call last):
  File "/home/vboxuser/Documents/Math-Odyssey/gen_formalizer/.venv/lib/python3.13/site-packages/litellm/llms/vertex_ai/gemini/vertex_and_google_ai_studio_gemini.py", line 1890, in completion
    response = client.post(url=url, headers=headers, json=data)  # type: ignore
  File "/home/vboxuser/Documents/Math-Odyssey/gen_formalizer/.venv/lib/python3.13/site-packages/litellm/llms/custom_httpx/http_handler.py", line 780, in post
    raise e
  File "/home/vboxuser/Documents/Math-Odyssey/gen_formalizer/.venv/lib/python3.13/site-packages/litellm/llms/custom_httpx/http_handler.py", line 762, in post
    response.raise_for_status()
    ~~~~~~~~~~~~~~~~~~~~~~~~~^^
  File "/home/vboxuser/Documents/Math-Odyssey/gen_formalizer/.venv/lib/python3.13/site-packages/httpx/_models.py", line 829, in raise_for_status
    raise HTTPStatusError(message, request=request, response=self)
httpx.HTTPStatusError: Server error '503 Service Unavailable' for url 'https://generativelanguage.googleapis.com/v1beta/models/gemini-2.5-flash:generateContent?key=AIzaSyDoL-8LOr6PUL1KLHCAQsSWl9uJ1PsMD7o'
For more information check: https://developer.mozilla.org/en-US/docs/Web/HTTP/Status/503

During handling of the above exception, another exception occurred:

Traceback (most recent call last):
  File "/home/vboxuser/Documents/Math-Odyssey/gen_formalizer/.venv/lib/python3.13/site-packages/litellm/main.py", line 2606, in completion
    response = vertex_chat_completion.completion(  # type: ignore
        model=model,
    ...<17 lines>...
        extra_headers=extra_headers,
    )
  File "/home/vboxuser/Documents/Math-Odyssey/gen_formalizer/.venv/lib/python3.13/site-packages/litellm/llms/vertex_ai/gemini/vertex_and_google_ai_studio_gemini.py", line 1894, in completion
    raise VertexAIError(
    ...<3 lines>...
    )
litellm.llms.vertex_ai.common_utils.VertexAIError: {
  "error": {
    "code": 503,
    "message": "The model is overloaded. Please try again later.",
    "status": "UNAVAILABLE"
  }
}


During handling of the above exception, another exception occurred:

Traceback (most recent call last):
  File "/home/vboxuser/Documents/Math-Odyssey/gen_formalizer/src/gen_formalizer/main.py", line 29, in run
    result = GenFormalizer().crew().kickoff(inputs=inputs)
  File "/home/vboxuser/Documents/Math-Odyssey/gen_formalizer/.venv/lib/python3.13/site-packages/crewai/crew.py", line 661, in kickoff
    result = self._run_sequential_process()
  File "/home/vboxuser/Documents/Math-Odyssey/gen_formalizer/.venv/lib/python3.13/site-packages/crewai/crew.py", line 772, in _run_sequential_process
    return self._execute_tasks(self.tasks)
           ~~~~~~~~~~~~~~~~~~~^^^^^^^^^^^^
  File "/home/vboxuser/Documents/Math-Odyssey/gen_formalizer/.venv/lib/python3.13/site-packages/crewai/crew.py", line 875, in _execute_tasks
    task_output = task.execute_sync(
        agent=agent_to_use,
        context=context,
        tools=cast(List[BaseTool], tools_for_task),
    )
  File "/home/vboxuser/Documents/Math-Odyssey/gen_formalizer/.venv/lib/python3.13/site-packages/crewai/task.py", line 382, in execute_sync
    return self._execute_core(agent, context, tools)
           ~~~~~~~~~~~~~~~~~~^^^^^^^^^^^^^^^^^^^^^^^
  File "/home/vboxuser/Documents/Math-Odyssey/gen_formalizer/.venv/lib/python3.13/site-packages/crewai/task.py", line 530, in _execute_core
    raise e  # Re-raise the exception after emitting the event
    ^^^^^^^
  File "/home/vboxuser/Documents/Math-Odyssey/gen_formalizer/.venv/lib/python3.13/site-packages/crewai/task.py", line 446, in _execute_core
    result = agent.execute_task(
        task=self,
        context=context,
        tools=tools,
    )
  File "/home/vboxuser/Documents/Math-Odyssey/gen_formalizer/.venv/lib/python3.13/site-packages/crewai/agent.py", line 475, in execute_task
    raise e
  File "/home/vboxuser/Documents/Math-Odyssey/gen_formalizer/.venv/lib/python3.13/site-packages/crewai/agent.py", line 451, in execute_task
    result = self._execute_without_timeout(task_prompt, task)
  File "/home/vboxuser/Documents/Math-Odyssey/gen_formalizer/.venv/lib/python3.13/site-packages/crewai/agent.py", line 547, in _execute_without_timeout
    return self.agent_executor.invoke(
           ~~~~~~~~~~~~~~~~~~~~~~~~~~^
        {
        ^
    ...<4 lines>...
        }
        ^
    )["output"]
    ^
  File "/home/vboxuser/Documents/Math-Odyssey/gen_formalizer/.venv/lib/python3.13/site-packages/crewai/agents/crew_agent_executor.py", line 114, in invoke
    formatted_answer = self._invoke_loop()
  File "/home/vboxuser/Documents/Math-Odyssey/gen_formalizer/.venv/lib/python3.13/site-packages/crewai/agents/crew_agent_executor.py", line 208, in _invoke_loop
    raise e
  File "/home/vboxuser/Documents/Math-Odyssey/gen_formalizer/.venv/lib/python3.13/site-packages/crewai/agents/crew_agent_executor.py", line 154, in _invoke_loop
    answer = get_llm_response(
        llm=self.llm,
    ...<3 lines>...
        from_task=self.task
    )
  File "/home/vboxuser/Documents/Math-Odyssey/gen_formalizer/.venv/lib/python3.13/site-packages/crewai/utilities/agent_utils.py", line 160, in get_llm_response
    raise e
  File "/home/vboxuser/Documents/Math-Odyssey/gen_formalizer/.venv/lib/python3.13/site-packages/crewai/utilities/agent_utils.py", line 153, in get_llm_response
    answer = llm.call(
        messages,
    ...<2 lines>...
        from_agent=from_agent,
    )
  File "/home/vboxuser/Documents/Math-Odyssey/gen_formalizer/.venv/lib/python3.13/site-packages/crewai/llm.py", line 1030, in call
    return self._handle_non_streaming_response(
           ~~~~~~~~~~~~~~~~~~~~~~~~~~~~~~~~~~~^
        params, callbacks, available_functions, from_task, from_agent
        ^^^^^^^^^^^^^^^^^^^^^^^^^^^^^^^^^^^^^^^^^^^^^^^^^^^^^^^^^^^^^
    )
    ^
  File "/home/vboxuser/Documents/Math-Odyssey/gen_formalizer/.venv/lib/python3.13/site-packages/crewai/llm.py", line 813, in _handle_non_streaming_response
    response = litellm.completion(**params)
  File "/home/vboxuser/Documents/Math-Odyssey/gen_formalizer/.venv/lib/python3.13/site-packages/litellm/utils.py", line 1330, in wrapper
    raise e
  File "/home/vboxuser/Documents/Math-Odyssey/gen_formalizer/.venv/lib/python3.13/site-packages/litellm/utils.py", line 1205, in wrapper
    result = original_function(*args, **kwargs)
  File "/home/vboxuser/Documents/Math-Odyssey/gen_formalizer/.venv/lib/python3.13/site-packages/litellm/main.py", line 3427, in completion
    raise exception_type(
          ~~~~~~~~~~~~~~^
        model=model,
        ^^^^^^^^^^^^
    ...<3 lines>...
        extra_kwargs=kwargs,
        ^^^^^^^^^^^^^^^^^^^^
    )
    ^
  File "/home/vboxuser/Documents/Math-Odyssey/gen_formalizer/.venv/lib/python3.13/site-packages/litellm/litellm_core_utils/exception_mapping_utils.py", line 2301, in exception_type
    raise e
  File "/home/vboxuser/Documents/Math-Odyssey/gen_formalizer/.venv/lib/python3.13/site-packages/litellm/litellm_core_utils/exception_mapping_utils.py", line 1284, in exception_type
    raise litellm.InternalServerError(
    ...<4 lines>...
    )
litellm.exceptions.InternalServerError: litellm.InternalServerError: litellm.InternalServerError: VertexAIException - {
  "error": {
    "code": 503,
    "message": "The model is overloaded. Please try again later.",
    "status": "UNAVAILABLE"
  }
}


During handling of the above exception, another exception occurred:

Traceback (most recent call last):
  File "/home/vboxuser/Documents/Math-Odyssey/gen_formalizer/.venv/bin/run_crew", line 10, in <module>
    sys.exit(run(sys.argv[1], sys.argv[2]))
             ~~~^^^^^^^^^^^^^^^^^^^^^^^^^^
  File "/home/vboxuser/Documents/Math-Odyssey/gen_formalizer/src/gen_formalizer/main.py", line 37, in run
    raise Exception(f"An error occurred while running the crew: {e}")
Exception: An error occurred while running the crew: litellm.InternalServerError: litellm.InternalServerError: VertexAIException - {
  "error": {
    "code": 503,
    "message": "The model is overloaded. Please try again later.",
    "status": "UNAVAILABLE"
  }
}

An error occurred while running the crew: Command '['uv', 'run', 'run_crew', 'In the convex quadrilateral $A B C D$ inscribed in a circle, if $\\overrightarrow{A B}+3 \\overrightarrow{B C}+2 \\overrightarrow{C D}+4 \\overrightarrow{D A}=0$, and $|\\overrightarrow{A C}|=4$, then the maximum of  $|\\overrightarrow{A B}|+|\\overrightarrow{B C}|$ is \\_\\_\\_\\_\\_.\n\\end{problem}\n\\noindent', '$4 \\sqrt{2}$\\\\\n\\noindent']' returned non-zero exit status 1.
Usage: crewai run [OPTIONS] QUESTION ANSWER
Try 'crewai run --help' for help.

Error: No such option: -3
Traceback (most recent call last):
  File "/home/vboxuser/Documents/Math-Odyssey/gen_formalizer/.venv/lib/python3.13/site-packages/litellm/llms/vertex_ai/gemini/vertex_and_google_ai_studio_gemini.py", line 1890, in completion
    response = client.post(url=url, headers=headers, json=data)  # type: ignore
  File "/home/vboxuser/Documents/Math-Odyssey/gen_formalizer/.venv/lib/python3.13/site-packages/litellm/llms/custom_httpx/http_handler.py", line 780, in post
    raise e
  File "/home/vboxuser/Documents/Math-Odyssey/gen_formalizer/.venv/lib/python3.13/site-packages/litellm/llms/custom_httpx/http_handler.py", line 762, in post
    response.raise_for_status()
    ~~~~~~~~~~~~~~~~~~~~~~~~~^^
  File "/home/vboxuser/Documents/Math-Odyssey/gen_formalizer/.venv/lib/python3.13/site-packages/httpx/_models.py", line 829, in raise_for_status
    raise HTTPStatusError(message, request=request, response=self)
httpx.HTTPStatusError: Server error '503 Service Unavailable' for url 'https://generativelanguage.googleapis.com/v1beta/models/gemini-2.5-flash:generateContent?key=AIzaSyDoL-8LOr6PUL1KLHCAQsSWl9uJ1PsMD7o'
For more information check: https://developer.mozilla.org/en-US/docs/Web/HTTP/Status/503

During handling of the above exception, another exception occurred:

Traceback (most recent call last):
  File "/home/vboxuser/Documents/Math-Odyssey/gen_formalizer/.venv/lib/python3.13/site-packages/litellm/main.py", line 2606, in completion
    response = vertex_chat_completion.completion(  # type: ignore
        model=model,
    ...<17 lines>...
        extra_headers=extra_headers,
    )
  File "/home/vboxuser/Documents/Math-Odyssey/gen_formalizer/.venv/lib/python3.13/site-packages/litellm/llms/vertex_ai/gemini/vertex_and_google_ai_studio_gemini.py", line 1894, in completion
    raise VertexAIError(
    ...<3 lines>...
    )
litellm.llms.vertex_ai.common_utils.VertexAIError: {
  "error": {
    "code": 503,
    "message": "The model is overloaded. Please try again later.",
    "status": "UNAVAILABLE"
  }
}


During handling of the above exception, another exception occurred:

Traceback (most recent call last):
  File "/home/vboxuser/Documents/Math-Odyssey/gen_formalizer/src/gen_formalizer/main.py", line 29, in run
    result = GenFormalizer().crew().kickoff(inputs=inputs)
  File "/home/vboxuser/Documents/Math-Odyssey/gen_formalizer/.venv/lib/python3.13/site-packages/crewai/crew.py", line 661, in kickoff
    result = self._run_sequential_process()
  File "/home/vboxuser/Documents/Math-Odyssey/gen_formalizer/.venv/lib/python3.13/site-packages/crewai/crew.py", line 772, in _run_sequential_process
    return self._execute_tasks(self.tasks)
           ~~~~~~~~~~~~~~~~~~~^^^^^^^^^^^^
  File "/home/vboxuser/Documents/Math-Odyssey/gen_formalizer/.venv/lib/python3.13/site-packages/crewai/crew.py", line 875, in _execute_tasks
    task_output = task.execute_sync(
        agent=agent_to_use,
        context=context,
        tools=cast(List[BaseTool], tools_for_task),
    )
  File "/home/vboxuser/Documents/Math-Odyssey/gen_formalizer/.venv/lib/python3.13/site-packages/crewai/task.py", line 382, in execute_sync
    return self._execute_core(agent, context, tools)
           ~~~~~~~~~~~~~~~~~~^^^^^^^^^^^^^^^^^^^^^^^
  File "/home/vboxuser/Documents/Math-Odyssey/gen_formalizer/.venv/lib/python3.13/site-packages/crewai/task.py", line 530, in _execute_core
    raise e  # Re-raise the exception after emitting the event
    ^^^^^^^
  File "/home/vboxuser/Documents/Math-Odyssey/gen_formalizer/.venv/lib/python3.13/site-packages/crewai/task.py", line 446, in _execute_core
    result = agent.execute_task(
        task=self,
        context=context,
        tools=tools,
    )
  File "/home/vboxuser/Documents/Math-Odyssey/gen_formalizer/.venv/lib/python3.13/site-packages/crewai/agent.py", line 475, in execute_task
    raise e
  File "/home/vboxuser/Documents/Math-Odyssey/gen_formalizer/.venv/lib/python3.13/site-packages/crewai/agent.py", line 451, in execute_task
    result = self._execute_without_timeout(task_prompt, task)
  File "/home/vboxuser/Documents/Math-Odyssey/gen_formalizer/.venv/lib/python3.13/site-packages/crewai/agent.py", line 547, in _execute_without_timeout
    return self.agent_executor.invoke(
           ~~~~~~~~~~~~~~~~~~~~~~~~~~^
        {
        ^
    ...<4 lines>...
        }
        ^
    )["output"]
    ^
  File "/home/vboxuser/Documents/Math-Odyssey/gen_formalizer/.venv/lib/python3.13/site-packages/crewai/agents/crew_agent_executor.py", line 114, in invoke
    formatted_answer = self._invoke_loop()
  File "/home/vboxuser/Documents/Math-Odyssey/gen_formalizer/.venv/lib/python3.13/site-packages/crewai/agents/crew_agent_executor.py", line 208, in _invoke_loop
    raise e
  File "/home/vboxuser/Documents/Math-Odyssey/gen_formalizer/.venv/lib/python3.13/site-packages/crewai/agents/crew_agent_executor.py", line 154, in _invoke_loop
    answer = get_llm_response(
        llm=self.llm,
    ...<3 lines>...
        from_task=self.task
    )
  File "/home/vboxuser/Documents/Math-Odyssey/gen_formalizer/.venv/lib/python3.13/site-packages/crewai/utilities/agent_utils.py", line 160, in get_llm_response
    raise e
  File "/home/vboxuser/Documents/Math-Odyssey/gen_formalizer/.venv/lib/python3.13/site-packages/crewai/utilities/agent_utils.py", line 153, in get_llm_response
    answer = llm.call(
        messages,
    ...<2 lines>...
        from_agent=from_agent,
    )
  File "/home/vboxuser/Documents/Math-Odyssey/gen_formalizer/.venv/lib/python3.13/site-packages/crewai/llm.py", line 1030, in call
    return self._handle_non_streaming_response(
           ~~~~~~~~~~~~~~~~~~~~~~~~~~~~~~~~~~~^
        params, callbacks, available_functions, from_task, from_agent
        ^^^^^^^^^^^^^^^^^^^^^^^^^^^^^^^^^^^^^^^^^^^^^^^^^^^^^^^^^^^^^
    )
    ^
  File "/home/vboxuser/Documents/Math-Odyssey/gen_formalizer/.venv/lib/python3.13/site-packages/crewai/llm.py", line 813, in _handle_non_streaming_response
    response = litellm.completion(**params)
  File "/home/vboxuser/Documents/Math-Odyssey/gen_formalizer/.venv/lib/python3.13/site-packages/litellm/utils.py", line 1330, in wrapper
    raise e
  File "/home/vboxuser/Documents/Math-Odyssey/gen_formalizer/.venv/lib/python3.13/site-packages/litellm/utils.py", line 1205, in wrapper
    result = original_function(*args, **kwargs)
  File "/home/vboxuser/Documents/Math-Odyssey/gen_formalizer/.venv/lib/python3.13/site-packages/litellm/main.py", line 3427, in completion
    raise exception_type(
          ~~~~~~~~~~~~~~^
        model=model,
        ^^^^^^^^^^^^
    ...<3 lines>...
        extra_kwargs=kwargs,
        ^^^^^^^^^^^^^^^^^^^^
    )
    ^
  File "/home/vboxuser/Documents/Math-Odyssey/gen_formalizer/.venv/lib/python3.13/site-packages/litellm/litellm_core_utils/exception_mapping_utils.py", line 2301, in exception_type
    raise e
  File "/home/vboxuser/Documents/Math-Odyssey/gen_formalizer/.venv/lib/python3.13/site-packages/litellm/litellm_core_utils/exception_mapping_utils.py", line 1284, in exception_type
    raise litellm.InternalServerError(
    ...<4 lines>...
    )
litellm.exceptions.InternalServerError: litellm.InternalServerError: litellm.InternalServerError: VertexAIException - {
  "error": {
    "code": 503,
    "message": "The model is overloaded. Please try again later.",
    "status": "UNAVAILABLE"
  }
}


During handling of the above exception, another exception occurred:

Traceback (most recent call last):
  File "/home/vboxuser/Documents/Math-Odyssey/gen_formalizer/.venv/bin/run_crew", line 10, in <module>
    sys.exit(run(sys.argv[1], sys.argv[2]))
             ~~~^^^^^^^^^^^^^^^^^^^^^^^^^^
  File "/home/vboxuser/Documents/Math-Odyssey/gen_formalizer/src/gen_formalizer/main.py", line 37, in run
    raise Exception(f"An error occurred while running the crew: {e}")
Exception: An error occurred while running the crew: litellm.InternalServerError: litellm.InternalServerError: VertexAIException - {
  "error": {
    "code": 503,
    "message": "The model is overloaded. Please try again later.",
    "status": "UNAVAILABLE"
  }
}

An error occurred while running the crew: Command '['uv', 'run', 'run_crew', 'Let $X_k$ be the time elapsed between the $(k-1)^{\\rm th}$ accident and the $k^{\\rm th}$ accident. Suppose $X_1, X_2, \\ldots $ are independent of each other. You use\n    the exponential distribution with probability density function $f(t) = 0.4e^{-0.4t}$, $t>0$ measured in minutes to model $X_k$. What is the probability of at least two accidents happening in a five-minute period?\n\\end{problem}\n\n\\noindent', '0.59 \\\\\n\\noindent']' returned non-zero exit status 1.
wrong: 20
correct: 80
\n
Usage: crewai run [OPTIONS] QUESTION ANSWER
Try 'crewai run --help' for help.

Error: No such option: -4
Traceback (most recent call last):
  File "/home/vboxuser/Documents/Math-Odyssey/gen_formalizer/.venv/lib/python3.13/site-packages/litellm/llms/vertex_ai/gemini/vertex_and_google_ai_studio_gemini.py", line 1890, in completion
    response = client.post(url=url, headers=headers, json=data)  # type: ignore
  File "/home/vboxuser/Documents/Math-Odyssey/gen_formalizer/.venv/lib/python3.13/site-packages/litellm/llms/custom_httpx/http_handler.py", line 780, in post
    raise e
  File "/home/vboxuser/Documents/Math-Odyssey/gen_formalizer/.venv/lib/python3.13/site-packages/litellm/llms/custom_httpx/http_handler.py", line 762, in post
    response.raise_for_status()
    ~~~~~~~~~~~~~~~~~~~~~~~~~^^
  File "/home/vboxuser/Documents/Math-Odyssey/gen_formalizer/.venv/lib/python3.13/site-packages/httpx/_models.py", line 829, in raise_for_status
    raise HTTPStatusError(message, request=request, response=self)
httpx.HTTPStatusError: Server error '503 Service Unavailable' for url 'https://generativelanguage.googleapis.com/v1beta/models/gemini-2.5-flash:generateContent?key=AIzaSyDoL-8LOr6PUL1KLHCAQsSWl9uJ1PsMD7o'
For more information check: https://developer.mozilla.org/en-US/docs/Web/HTTP/Status/503

During handling of the above exception, another exception occurred:

Traceback (most recent call last):
  File "/home/vboxuser/Documents/Math-Odyssey/gen_formalizer/.venv/lib/python3.13/site-packages/litellm/main.py", line 2606, in completion
    response = vertex_chat_completion.completion(  # type: ignore
        model=model,
    ...<17 lines>...
        extra_headers=extra_headers,
    )
  File "/home/vboxuser/Documents/Math-Odyssey/gen_formalizer/.venv/lib/python3.13/site-packages/litellm/llms/vertex_ai/gemini/vertex_and_google_ai_studio_gemini.py", line 1894, in completion
    raise VertexAIError(
    ...<3 lines>...
    )
litellm.llms.vertex_ai.common_utils.VertexAIError: {
  "error": {
    "code": 503,
    "message": "The model is overloaded. Please try again later.",
    "status": "UNAVAILABLE"
  }
}


During handling of the above exception, another exception occurred:

Traceback (most recent call last):
  File "/home/vboxuser/Documents/Math-Odyssey/gen_formalizer/src/gen_formalizer/main.py", line 29, in run
    result = GenFormalizer().crew().kickoff(inputs=inputs)
  File "/home/vboxuser/Documents/Math-Odyssey/gen_formalizer/.venv/lib/python3.13/site-packages/crewai/crew.py", line 661, in kickoff
    result = self._run_sequential_process()
  File "/home/vboxuser/Documents/Math-Odyssey/gen_formalizer/.venv/lib/python3.13/site-packages/crewai/crew.py", line 772, in _run_sequential_process
    return self._execute_tasks(self.tasks)
           ~~~~~~~~~~~~~~~~~~~^^^^^^^^^^^^
  File "/home/vboxuser/Documents/Math-Odyssey/gen_formalizer/.venv/lib/python3.13/site-packages/crewai/crew.py", line 875, in _execute_tasks
    task_output = task.execute_sync(
        agent=agent_to_use,
        context=context,
        tools=cast(List[BaseTool], tools_for_task),
    )
  File "/home/vboxuser/Documents/Math-Odyssey/gen_formalizer/.venv/lib/python3.13/site-packages/crewai/task.py", line 382, in execute_sync
    return self._execute_core(agent, context, tools)
           ~~~~~~~~~~~~~~~~~~^^^^^^^^^^^^^^^^^^^^^^^
  File "/home/vboxuser/Documents/Math-Odyssey/gen_formalizer/.venv/lib/python3.13/site-packages/crewai/task.py", line 530, in _execute_core
    raise e  # Re-raise the exception after emitting the event
    ^^^^^^^
  File "/home/vboxuser/Documents/Math-Odyssey/gen_formalizer/.venv/lib/python3.13/site-packages/crewai/task.py", line 446, in _execute_core
    result = agent.execute_task(
        task=self,
        context=context,
        tools=tools,
    )
  File "/home/vboxuser/Documents/Math-Odyssey/gen_formalizer/.venv/lib/python3.13/site-packages/crewai/agent.py", line 475, in execute_task
    raise e
  File "/home/vboxuser/Documents/Math-Odyssey/gen_formalizer/.venv/lib/python3.13/site-packages/crewai/agent.py", line 451, in execute_task
    result = self._execute_without_timeout(task_prompt, task)
  File "/home/vboxuser/Documents/Math-Odyssey/gen_formalizer/.venv/lib/python3.13/site-packages/crewai/agent.py", line 547, in _execute_without_timeout
    return self.agent_executor.invoke(
           ~~~~~~~~~~~~~~~~~~~~~~~~~~^
        {
        ^
    ...<4 lines>...
        }
        ^
    )["output"]
    ^
  File "/home/vboxuser/Documents/Math-Odyssey/gen_formalizer/.venv/lib/python3.13/site-packages/crewai/agents/crew_agent_executor.py", line 114, in invoke
    formatted_answer = self._invoke_loop()
  File "/home/vboxuser/Documents/Math-Odyssey/gen_formalizer/.venv/lib/python3.13/site-packages/crewai/agents/crew_agent_executor.py", line 208, in _invoke_loop
    raise e
  File "/home/vboxuser/Documents/Math-Odyssey/gen_formalizer/.venv/lib/python3.13/site-packages/crewai/agents/crew_agent_executor.py", line 154, in _invoke_loop
    answer = get_llm_response(
        llm=self.llm,
    ...<3 lines>...
        from_task=self.task
    )
  File "/home/vboxuser/Documents/Math-Odyssey/gen_formalizer/.venv/lib/python3.13/site-packages/crewai/utilities/agent_utils.py", line 160, in get_llm_response
    raise e
  File "/home/vboxuser/Documents/Math-Odyssey/gen_formalizer/.venv/lib/python3.13/site-packages/crewai/utilities/agent_utils.py", line 153, in get_llm_response
    answer = llm.call(
        messages,
    ...<2 lines>...
        from_agent=from_agent,
    )
  File "/home/vboxuser/Documents/Math-Odyssey/gen_formalizer/.venv/lib/python3.13/site-packages/crewai/llm.py", line 1030, in call
    return self._handle_non_streaming_response(
           ~~~~~~~~~~~~~~~~~~~~~~~~~~~~~~~~~~~^
        params, callbacks, available_functions, from_task, from_agent
        ^^^^^^^^^^^^^^^^^^^^^^^^^^^^^^^^^^^^^^^^^^^^^^^^^^^^^^^^^^^^^
    )
    ^
  File "/home/vboxuser/Documents/Math-Odyssey/gen_formalizer/.venv/lib/python3.13/site-packages/crewai/llm.py", line 813, in _handle_non_streaming_response
    response = litellm.completion(**params)
  File "/home/vboxuser/Documents/Math-Odyssey/gen_formalizer/.venv/lib/python3.13/site-packages/litellm/utils.py", line 1330, in wrapper
    raise e
  File "/home/vboxuser/Documents/Math-Odyssey/gen_formalizer/.venv/lib/python3.13/site-packages/litellm/utils.py", line 1205, in wrapper
    result = original_function(*args, **kwargs)
  File "/home/vboxuser/Documents/Math-Odyssey/gen_formalizer/.venv/lib/python3.13/site-packages/litellm/main.py", line 3427, in completion
    raise exception_type(
          ~~~~~~~~~~~~~~^
        model=model,
        ^^^^^^^^^^^^
    ...<3 lines>...
        extra_kwargs=kwargs,
        ^^^^^^^^^^^^^^^^^^^^
    )
    ^
  File "/home/vboxuser/Documents/Math-Odyssey/gen_formalizer/.venv/lib/python3.13/site-packages/litellm/litellm_core_utils/exception_mapping_utils.py", line 2301, in exception_type
    raise e
  File "/home/vboxuser/Documents/Math-Odyssey/gen_formalizer/.venv/lib/python3.13/site-packages/litellm/litellm_core_utils/exception_mapping_utils.py", line 1284, in exception_type
    raise litellm.InternalServerError(
    ...<4 lines>...
    )
litellm.exceptions.InternalServerError: litellm.InternalServerError: litellm.InternalServerError: VertexAIException - {
  "error": {
    "code": 503,
    "message": "The model is overloaded. Please try again later.",
    "status": "UNAVAILABLE"
  }
}


During handling of the above exception, another exception occurred:

Traceback (most recent call last):
  File "/home/vboxuser/Documents/Math-Odyssey/gen_formalizer/.venv/bin/run_crew", line 10, in <module>
    sys.exit(run(sys.argv[1], sys.argv[2]))
             ~~~^^^^^^^^^^^^^^^^^^^^^^^^^^
  File "/home/vboxuser/Documents/Math-Odyssey/gen_formalizer/src/gen_formalizer/main.py", line 37, in run
    raise Exception(f"An error occurred while running the crew: {e}")
Exception: An error occurred while running the crew: litellm.InternalServerError: litellm.InternalServerError: VertexAIException - {
  "error": {
    "code": 503,
    "message": "The model is overloaded. Please try again later.",
    "status": "UNAVAILABLE"
  }
}

An error occurred while running the crew: Command '['uv', 'run', 'run_crew', 'Evaluate \\( \\tan(\\alpha - \\beta) \\) given: \\( \\tan\\alpha = -\\frac{4}{3}, \\frac{\\pi}{2} < \\alpha < \\pi \\) and \\( \\cos\\beta = \\frac{1}{2}, 0 < \\beta < \\frac{\\pi}{2} \\).\n\n\\noindent Options:\\\\\nA) \\( \\frac{25\\sqrt{3} + 48}{39} \\)\\\\\nB) \\( -\\frac{25\\sqrt{3} + 48}{39} \\)\\\\\nC) \\( \\frac{16 + 7\\sqrt{3}}{47} \\)\\\\\nD) \\( -\\frac{16 + 7\\sqrt{3}}{47} \\)\n\\end{problem}\n\n\\noindent', 'A\n\n\\noindent']' returned non-zero exit status 1.
wrong: 24
correct: 76
\n
Usage: crewai run [OPTIONS] QUESTION ANSWER
Try 'crewai run --help' for help.

Error: No such option: -1
Usage: crewai run [OPTIONS] QUESTION ANSWER
Try 'crewai run --help' for help.

Error: No such option: -4
Traceback (most recent call last):
  File "/home/vboxuser/Documents/Math-Odyssey/gen_formalizer/.venv/lib/python3.13/site-packages/litellm/llms/vertex_ai/gemini/vertex_and_google_ai_studio_gemini.py", line 1890, in completion
    response = client.post(url=url, headers=headers, json=data)  # type: ignore
  File "/home/vboxuser/Documents/Math-Odyssey/gen_formalizer/.venv/lib/python3.13/site-packages/litellm/llms/custom_httpx/http_handler.py", line 780, in post
    raise e
  File "/home/vboxuser/Documents/Math-Odyssey/gen_formalizer/.venv/lib/python3.13/site-packages/litellm/llms/custom_httpx/http_handler.py", line 762, in post
    response.raise_for_status()
    ~~~~~~~~~~~~~~~~~~~~~~~~~^^
  File "/home/vboxuser/Documents/Math-Odyssey/gen_formalizer/.venv/lib/python3.13/site-packages/httpx/_models.py", line 829, in raise_for_status
    raise HTTPStatusError(message, request=request, response=self)
httpx.HTTPStatusError: Server error '503 Service Unavailable' for url 'https://generativelanguage.googleapis.com/v1beta/models/gemini-2.5-flash:generateContent?key=AIzaSyDoL-8LOr6PUL1KLHCAQsSWl9uJ1PsMD7o'
For more information check: https://developer.mozilla.org/en-US/docs/Web/HTTP/Status/503

During handling of the above exception, another exception occurred:

Traceback (most recent call last):
  File "/home/vboxuser/Documents/Math-Odyssey/gen_formalizer/.venv/lib/python3.13/site-packages/litellm/main.py", line 2606, in completion
    response = vertex_chat_completion.completion(  # type: ignore
        model=model,
    ...<17 lines>...
        extra_headers=extra_headers,
    )
  File "/home/vboxuser/Documents/Math-Odyssey/gen_formalizer/.venv/lib/python3.13/site-packages/litellm/llms/vertex_ai/gemini/vertex_and_google_ai_studio_gemini.py", line 1894, in completion
    raise VertexAIError(
    ...<3 lines>...
    )
litellm.llms.vertex_ai.common_utils.VertexAIError: {
  "error": {
    "code": 503,
    "message": "The service is currently unavailable.",
    "status": "UNAVAILABLE"
  }
}


During handling of the above exception, another exception occurred:

Traceback (most recent call last):
  File "/home/vboxuser/Documents/Math-Odyssey/gen_formalizer/src/gen_formalizer/main.py", line 29, in run
    result = GenFormalizer().crew().kickoff(inputs=inputs)
  File "/home/vboxuser/Documents/Math-Odyssey/gen_formalizer/.venv/lib/python3.13/site-packages/crewai/crew.py", line 661, in kickoff
    result = self._run_sequential_process()
  File "/home/vboxuser/Documents/Math-Odyssey/gen_formalizer/.venv/lib/python3.13/site-packages/crewai/crew.py", line 772, in _run_sequential_process
    return self._execute_tasks(self.tasks)
           ~~~~~~~~~~~~~~~~~~~^^^^^^^^^^^^
  File "/home/vboxuser/Documents/Math-Odyssey/gen_formalizer/.venv/lib/python3.13/site-packages/crewai/crew.py", line 875, in _execute_tasks
    task_output = task.execute_sync(
        agent=agent_to_use,
        context=context,
        tools=cast(List[BaseTool], tools_for_task),
    )
  File "/home/vboxuser/Documents/Math-Odyssey/gen_formalizer/.venv/lib/python3.13/site-packages/crewai/task.py", line 382, in execute_sync
    return self._execute_core(agent, context, tools)
           ~~~~~~~~~~~~~~~~~~^^^^^^^^^^^^^^^^^^^^^^^
  File "/home/vboxuser/Documents/Math-Odyssey/gen_formalizer/.venv/lib/python3.13/site-packages/crewai/task.py", line 530, in _execute_core
    raise e  # Re-raise the exception after emitting the event
    ^^^^^^^
  File "/home/vboxuser/Documents/Math-Odyssey/gen_formalizer/.venv/lib/python3.13/site-packages/crewai/task.py", line 446, in _execute_core
    result = agent.execute_task(
        task=self,
        context=context,
        tools=tools,
    )
  File "/home/vboxuser/Documents/Math-Odyssey/gen_formalizer/.venv/lib/python3.13/site-packages/crewai/agent.py", line 475, in execute_task
    raise e
  File "/home/vboxuser/Documents/Math-Odyssey/gen_formalizer/.venv/lib/python3.13/site-packages/crewai/agent.py", line 451, in execute_task
    result = self._execute_without_timeout(task_prompt, task)
  File "/home/vboxuser/Documents/Math-Odyssey/gen_formalizer/.venv/lib/python3.13/site-packages/crewai/agent.py", line 547, in _execute_without_timeout
    return self.agent_executor.invoke(
           ~~~~~~~~~~~~~~~~~~~~~~~~~~^
        {
        ^
    ...<4 lines>...
        }
        ^
    )["output"]
    ^
  File "/home/vboxuser/Documents/Math-Odyssey/gen_formalizer/.venv/lib/python3.13/site-packages/crewai/agents/crew_agent_executor.py", line 114, in invoke
    formatted_answer = self._invoke_loop()
  File "/home/vboxuser/Documents/Math-Odyssey/gen_formalizer/.venv/lib/python3.13/site-packages/crewai/agents/crew_agent_executor.py", line 208, in _invoke_loop
    raise e
  File "/home/vboxuser/Documents/Math-Odyssey/gen_formalizer/.venv/lib/python3.13/site-packages/crewai/agents/crew_agent_executor.py", line 154, in _invoke_loop
    answer = get_llm_response(
        llm=self.llm,
    ...<3 lines>...
        from_task=self.task
    )
  File "/home/vboxuser/Documents/Math-Odyssey/gen_formalizer/.venv/lib/python3.13/site-packages/crewai/utilities/agent_utils.py", line 160, in get_llm_response
    raise e
  File "/home/vboxuser/Documents/Math-Odyssey/gen_formalizer/.venv/lib/python3.13/site-packages/crewai/utilities/agent_utils.py", line 153, in get_llm_response
    answer = llm.call(
        messages,
    ...<2 lines>...
        from_agent=from_agent,
    )
  File "/home/vboxuser/Documents/Math-Odyssey/gen_formalizer/.venv/lib/python3.13/site-packages/crewai/llm.py", line 1030, in call
    return self._handle_non_streaming_response(
           ~~~~~~~~~~~~~~~~~~~~~~~~~~~~~~~~~~~^
        params, callbacks, available_functions, from_task, from_agent
        ^^^^^^^^^^^^^^^^^^^^^^^^^^^^^^^^^^^^^^^^^^^^^^^^^^^^^^^^^^^^^
    )
    ^
  File "/home/vboxuser/Documents/Math-Odyssey/gen_formalizer/.venv/lib/python3.13/site-packages/crewai/llm.py", line 813, in _handle_non_streaming_response
    response = litellm.completion(**params)
  File "/home/vboxuser/Documents/Math-Odyssey/gen_formalizer/.venv/lib/python3.13/site-packages/litellm/utils.py", line 1330, in wrapper
    raise e
  File "/home/vboxuser/Documents/Math-Odyssey/gen_formalizer/.venv/lib/python3.13/site-packages/litellm/utils.py", line 1205, in wrapper
    result = original_function(*args, **kwargs)
  File "/home/vboxuser/Documents/Math-Odyssey/gen_formalizer/.venv/lib/python3.13/site-packages/litellm/main.py", line 3427, in completion
    raise exception_type(
          ~~~~~~~~~~~~~~^
        model=model,
        ^^^^^^^^^^^^
    ...<3 lines>...
        extra_kwargs=kwargs,
        ^^^^^^^^^^^^^^^^^^^^
    )
    ^
  File "/home/vboxuser/Documents/Math-Odyssey/gen_formalizer/.venv/lib/python3.13/site-packages/litellm/litellm_core_utils/exception_mapping_utils.py", line 2301, in exception_type
    raise e
  File "/home/vboxuser/Documents/Math-Odyssey/gen_formalizer/.venv/lib/python3.13/site-packages/litellm/litellm_core_utils/exception_mapping_utils.py", line 1358, in exception_type
    raise ServiceUnavailableError(
    ...<3 lines>...
    )
litellm.exceptions.ServiceUnavailableError: litellm.ServiceUnavailableError: VertexAIException - {
  "error": {
    "code": 503,
    "message": "The service is currently unavailable.",
    "status": "UNAVAILABLE"
  }
}


During handling of the above exception, another exception occurred:

Traceback (most recent call last):
  File "/home/vboxuser/Documents/Math-Odyssey/gen_formalizer/.venv/bin/run_crew", line 10, in <module>
    sys.exit(run(sys.argv[1], sys.argv[2]))
             ~~~^^^^^^^^^^^^^^^^^^^^^^^^^^
  File "/home/vboxuser/Documents/Math-Odyssey/gen_formalizer/src/gen_formalizer/main.py", line 37, in run
    raise Exception(f"An error occurred while running the crew: {e}")
Exception: An error occurred while running the crew: litellm.ServiceUnavailableError: VertexAIException - {
  "error": {
    "code": 503,
    "message": "The service is currently unavailable.",
    "status": "UNAVAILABLE"
  }
}

An error occurred while running the crew: Command '['uv', 'run', 'run_crew', 'Let $X_k$ be the time elapsed between the $(k-1)^{\\rm th}$ accident and the $k^{\\rm th}$ accident. Suppose $X_1, X_2, \\ldots $ are independent of each other. You use\n    the exponential distribution with probability density function $f(t) = 0.4e^{-0.4t}$, $t>0$ measured in minutes to model $X_k$. What is the probability of at least two accidents happening in a five-minute period?\n\\end{problem}\n\n\\noindent', '0.59 \\\\\n\\noindent']' returned non-zero exit status 1.
wrong: 19
correct: 81
\n
Traceback (most recent call last):
  File "/home/vboxuser/Documents/Math-Odyssey/gen_formalizer/.venv/lib/python3.13/site-packages/litellm/llms/vertex_ai/gemini/vertex_and_google_ai_studio_gemini.py", line 1890, in completion
    response = client.post(url=url, headers=headers, json=data)  # type: ignore
  File "/home/vboxuser/Documents/Math-Odyssey/gen_formalizer/.venv/lib/python3.13/site-packages/litellm/llms/custom_httpx/http_handler.py", line 780, in post
    raise e
  File "/home/vboxuser/Documents/Math-Odyssey/gen_formalizer/.venv/lib/python3.13/site-packages/litellm/llms/custom_httpx/http_handler.py", line 762, in post
    response.raise_for_status()
    ~~~~~~~~~~~~~~~~~~~~~~~~~^^
  File "/home/vboxuser/Documents/Math-Odyssey/gen_formalizer/.venv/lib/python3.13/site-packages/httpx/_models.py", line 829, in raise_for_status
    raise HTTPStatusError(message, request=request, response=self)
httpx.HTTPStatusError: Server error '503 Service Unavailable' for url 'https://generativelanguage.googleapis.com/v1beta/models/gemini-2.5-flash:generateContent?key=AIzaSyDoL-8LOr6PUL1KLHCAQsSWl9uJ1PsMD7o'
For more information check: https://developer.mozilla.org/en-US/docs/Web/HTTP/Status/503

During handling of the above exception, another exception occurred:

Traceback (most recent call last):
  File "/home/vboxuser/Documents/Math-Odyssey/gen_formalizer/.venv/lib/python3.13/site-packages/litellm/main.py", line 2606, in completion
    response = vertex_chat_completion.completion(  # type: ignore
        model=model,
    ...<17 lines>...
        extra_headers=extra_headers,
    )
  File "/home/vboxuser/Documents/Math-Odyssey/gen_formalizer/.venv/lib/python3.13/site-packages/litellm/llms/vertex_ai/gemini/vertex_and_google_ai_studio_gemini.py", line 1894, in completion
    raise VertexAIError(
    ...<3 lines>...
    )
litellm.llms.vertex_ai.common_utils.VertexAIError: {
  "error": {
    "code": 503,
    "message": "The model is overloaded. Please try again later.",
    "status": "UNAVAILABLE"
  }
}


During handling of the above exception, another exception occurred:

Traceback (most recent call last):
  File "/home/vboxuser/Documents/Math-Odyssey/gen_formalizer/src/gen_formalizer/main.py", line 29, in run
    result = GenFormalizer().crew().kickoff(inputs=inputs)
  File "/home/vboxuser/Documents/Math-Odyssey/gen_formalizer/.venv/lib/python3.13/site-packages/crewai/crew.py", line 661, in kickoff
    result = self._run_sequential_process()
  File "/home/vboxuser/Documents/Math-Odyssey/gen_formalizer/.venv/lib/python3.13/site-packages/crewai/crew.py", line 772, in _run_sequential_process
    return self._execute_tasks(self.tasks)
           ~~~~~~~~~~~~~~~~~~~^^^^^^^^^^^^
  File "/home/vboxuser/Documents/Math-Odyssey/gen_formalizer/.venv/lib/python3.13/site-packages/crewai/crew.py", line 875, in _execute_tasks
    task_output = task.execute_sync(
        agent=agent_to_use,
        context=context,
        tools=cast(List[BaseTool], tools_for_task),
    )
  File "/home/vboxuser/Documents/Math-Odyssey/gen_formalizer/.venv/lib/python3.13/site-packages/crewai/task.py", line 382, in execute_sync
    return self._execute_core(agent, context, tools)
           ~~~~~~~~~~~~~~~~~~^^^^^^^^^^^^^^^^^^^^^^^
  File "/home/vboxuser/Documents/Math-Odyssey/gen_formalizer/.venv/lib/python3.13/site-packages/crewai/task.py", line 530, in _execute_core
    raise e  # Re-raise the exception after emitting the event
    ^^^^^^^
  File "/home/vboxuser/Documents/Math-Odyssey/gen_formalizer/.venv/lib/python3.13/site-packages/crewai/task.py", line 446, in _execute_core
    result = agent.execute_task(
        task=self,
        context=context,
        tools=tools,
    )
  File "/home/vboxuser/Documents/Math-Odyssey/gen_formalizer/.venv/lib/python3.13/site-packages/crewai/agent.py", line 475, in execute_task
    raise e
  File "/home/vboxuser/Documents/Math-Odyssey/gen_formalizer/.venv/lib/python3.13/site-packages/crewai/agent.py", line 451, in execute_task
    result = self._execute_without_timeout(task_prompt, task)
  File "/home/vboxuser/Documents/Math-Odyssey/gen_formalizer/.venv/lib/python3.13/site-packages/crewai/agent.py", line 547, in _execute_without_timeout
    return self.agent_executor.invoke(
           ~~~~~~~~~~~~~~~~~~~~~~~~~~^
        {
        ^
    ...<4 lines>...
        }
        ^
    )["output"]
    ^
  File "/home/vboxuser/Documents/Math-Odyssey/gen_formalizer/.venv/lib/python3.13/site-packages/crewai/agents/crew_agent_executor.py", line 114, in invoke
    formatted_answer = self._invoke_loop()
  File "/home/vboxuser/Documents/Math-Odyssey/gen_formalizer/.venv/lib/python3.13/site-packages/crewai/agents/crew_agent_executor.py", line 208, in _invoke_loop
    raise e
  File "/home/vboxuser/Documents/Math-Odyssey/gen_formalizer/.venv/lib/python3.13/site-packages/crewai/agents/crew_agent_executor.py", line 154, in _invoke_loop
    answer = get_llm_response(
        llm=self.llm,
    ...<3 lines>...
        from_task=self.task
    )
  File "/home/vboxuser/Documents/Math-Odyssey/gen_formalizer/.venv/lib/python3.13/site-packages/crewai/utilities/agent_utils.py", line 160, in get_llm_response
    raise e
  File "/home/vboxuser/Documents/Math-Odyssey/gen_formalizer/.venv/lib/python3.13/site-packages/crewai/utilities/agent_utils.py", line 153, in get_llm_response
    answer = llm.call(
        messages,
    ...<2 lines>...
        from_agent=from_agent,
    )
  File "/home/vboxuser/Documents/Math-Odyssey/gen_formalizer/.venv/lib/python3.13/site-packages/crewai/llm.py", line 1030, in call
    return self._handle_non_streaming_response(
           ~~~~~~~~~~~~~~~~~~~~~~~~~~~~~~~~~~~^
        params, callbacks, available_functions, from_task, from_agent
        ^^^^^^^^^^^^^^^^^^^^^^^^^^^^^^^^^^^^^^^^^^^^^^^^^^^^^^^^^^^^^
    )
    ^
  File "/home/vboxuser/Documents/Math-Odyssey/gen_formalizer/.venv/lib/python3.13/site-packages/crewai/llm.py", line 813, in _handle_non_streaming_response
    response = litellm.completion(**params)
  File "/home/vboxuser/Documents/Math-Odyssey/gen_formalizer/.venv/lib/python3.13/site-packages/litellm/utils.py", line 1330, in wrapper
    raise e
  File "/home/vboxuser/Documents/Math-Odyssey/gen_formalizer/.venv/lib/python3.13/site-packages/litellm/utils.py", line 1205, in wrapper
    result = original_function(*args, **kwargs)
  File "/home/vboxuser/Documents/Math-Odyssey/gen_formalizer/.venv/lib/python3.13/site-packages/litellm/main.py", line 3427, in completion
    raise exception_type(
          ~~~~~~~~~~~~~~^
        model=model,
        ^^^^^^^^^^^^
    ...<3 lines>...
        extra_kwargs=kwargs,
        ^^^^^^^^^^^^^^^^^^^^
    )
    ^
  File "/home/vboxuser/Documents/Math-Odyssey/gen_formalizer/.venv/lib/python3.13/site-packages/litellm/litellm_core_utils/exception_mapping_utils.py", line 2301, in exception_type
    raise e
  File "/home/vboxuser/Documents/Math-Odyssey/gen_formalizer/.venv/lib/python3.13/site-packages/litellm/litellm_core_utils/exception_mapping_utils.py", line 1284, in exception_type
    raise litellm.InternalServerError(
    ...<4 lines>...
    )
litellm.exceptions.InternalServerError: litellm.InternalServerError: litellm.InternalServerError: VertexAIException - {
  "error": {
    "code": 503,
    "message": "The model is overloaded. Please try again later.",
    "status": "UNAVAILABLE"
  }
}


During handling of the above exception, another exception occurred:

Traceback (most recent call last):
  File "/home/vboxuser/Documents/Math-Odyssey/gen_formalizer/.venv/bin/run_crew", line 10, in <module>
    sys.exit(run(sys.argv[1], sys.argv[2]))
             ~~~^^^^^^^^^^^^^^^^^^^^^^^^^^
  File "/home/vboxuser/Documents/Math-Odyssey/gen_formalizer/src/gen_formalizer/main.py", line 37, in run
    raise Exception(f"An error occurred while running the crew: {e}")
Exception: An error occurred while running the crew: litellm.InternalServerError: litellm.InternalServerError: VertexAIException - {
  "error": {
    "code": 503,
    "message": "The model is overloaded. Please try again later.",
    "status": "UNAVAILABLE"
  }
}

An error occurred while running the crew: Command '['uv', 'run', 'run_crew', 'Given $x$ and $y$ are prime numbers. The sum of the values of $y$ in the solutions of the indeterminate equation $x^2-y^2=xy^2-19$ is \\underline{\\hspace{2cm}}.\n\\end{problem}\n\\noindent', '10\\\\\n\\noindent']' returned non-zero exit status 1.
Usage: crewai run [OPTIONS] QUESTION ANSWER
Try 'crewai run --help' for help.

Error: No such option: -2
Usage: crewai run [OPTIONS] QUESTION ANSWER
Try 'crewai run --help' for help.

Error: No such option: -0
wrong: 12
correct: 88
\n
Traceback (most recent call last):
  File "/home/vboxuser/Documents/Math-Odyssey/gen_formalizer/.venv/lib/python3.13/site-packages/litellm/llms/vertex_ai/gemini/vertex_and_google_ai_studio_gemini.py", line 1890, in completion
    response = client.post(url=url, headers=headers, json=data)  # type: ignore
  File "/home/vboxuser/Documents/Math-Odyssey/gen_formalizer/.venv/lib/python3.13/site-packages/litellm/llms/custom_httpx/http_handler.py", line 780, in post
    raise e
  File "/home/vboxuser/Documents/Math-Odyssey/gen_formalizer/.venv/lib/python3.13/site-packages/litellm/llms/custom_httpx/http_handler.py", line 762, in post
    response.raise_for_status()
    ~~~~~~~~~~~~~~~~~~~~~~~~~^^
  File "/home/vboxuser/Documents/Math-Odyssey/gen_formalizer/.venv/lib/python3.13/site-packages/httpx/_models.py", line 829, in raise_for_status
    raise HTTPStatusError(message, request=request, response=self)
httpx.HTTPStatusError: Server error '503 Service Unavailable' for url 'https://generativelanguage.googleapis.com/v1beta/models/gemini-2.5-flash:generateContent?key=AIzaSyDoL-8LOr6PUL1KLHCAQsSWl9uJ1PsMD7o'
For more information check: https://developer.mozilla.org/en-US/docs/Web/HTTP/Status/503

During handling of the above exception, another exception occurred:

Traceback (most recent call last):
  File "/home/vboxuser/Documents/Math-Odyssey/gen_formalizer/.venv/lib/python3.13/site-packages/litellm/main.py", line 2606, in completion
    response = vertex_chat_completion.completion(  # type: ignore
        model=model,
    ...<17 lines>...
        extra_headers=extra_headers,
    )
  File "/home/vboxuser/Documents/Math-Odyssey/gen_formalizer/.venv/lib/python3.13/site-packages/litellm/llms/vertex_ai/gemini/vertex_and_google_ai_studio_gemini.py", line 1894, in completion
    raise VertexAIError(
    ...<3 lines>...
    )
litellm.llms.vertex_ai.common_utils.VertexAIError: {
  "error": {
    "code": 503,
    "message": "The model is overloaded. Please try again later.",
    "status": "UNAVAILABLE"
  }
}


During handling of the above exception, another exception occurred:

Traceback (most recent call last):
  File "/home/vboxuser/Documents/Math-Odyssey/gen_formalizer/src/gen_formalizer/main.py", line 29, in run
    result = GenFormalizer().crew().kickoff(inputs=inputs)
  File "/home/vboxuser/Documents/Math-Odyssey/gen_formalizer/.venv/lib/python3.13/site-packages/crewai/crew.py", line 661, in kickoff
    result = self._run_sequential_process()
  File "/home/vboxuser/Documents/Math-Odyssey/gen_formalizer/.venv/lib/python3.13/site-packages/crewai/crew.py", line 772, in _run_sequential_process
    return self._execute_tasks(self.tasks)
           ~~~~~~~~~~~~~~~~~~~^^^^^^^^^^^^
  File "/home/vboxuser/Documents/Math-Odyssey/gen_formalizer/.venv/lib/python3.13/site-packages/crewai/crew.py", line 875, in _execute_tasks
    task_output = task.execute_sync(
        agent=agent_to_use,
        context=context,
        tools=cast(List[BaseTool], tools_for_task),
    )
  File "/home/vboxuser/Documents/Math-Odyssey/gen_formalizer/.venv/lib/python3.13/site-packages/crewai/task.py", line 382, in execute_sync
    return self._execute_core(agent, context, tools)
           ~~~~~~~~~~~~~~~~~~^^^^^^^^^^^^^^^^^^^^^^^
  File "/home/vboxuser/Documents/Math-Odyssey/gen_formalizer/.venv/lib/python3.13/site-packages/crewai/task.py", line 530, in _execute_core
    raise e  # Re-raise the exception after emitting the event
    ^^^^^^^
  File "/home/vboxuser/Documents/Math-Odyssey/gen_formalizer/.venv/lib/python3.13/site-packages/crewai/task.py", line 446, in _execute_core
    result = agent.execute_task(
        task=self,
        context=context,
        tools=tools,
    )
  File "/home/vboxuser/Documents/Math-Odyssey/gen_formalizer/.venv/lib/python3.13/site-packages/crewai/agent.py", line 475, in execute_task
    raise e
  File "/home/vboxuser/Documents/Math-Odyssey/gen_formalizer/.venv/lib/python3.13/site-packages/crewai/agent.py", line 451, in execute_task
    result = self._execute_without_timeout(task_prompt, task)
  File "/home/vboxuser/Documents/Math-Odyssey/gen_formalizer/.venv/lib/python3.13/site-packages/crewai/agent.py", line 547, in _execute_without_timeout
    return self.agent_executor.invoke(
           ~~~~~~~~~~~~~~~~~~~~~~~~~~^
        {
        ^
    ...<4 lines>...
        }
        ^
    )["output"]
    ^
  File "/home/vboxuser/Documents/Math-Odyssey/gen_formalizer/.venv/lib/python3.13/site-packages/crewai/agents/crew_agent_executor.py", line 114, in invoke
    formatted_answer = self._invoke_loop()
  File "/home/vboxuser/Documents/Math-Odyssey/gen_formalizer/.venv/lib/python3.13/site-packages/crewai/agents/crew_agent_executor.py", line 208, in _invoke_loop
    raise e
  File "/home/vboxuser/Documents/Math-Odyssey/gen_formalizer/.venv/lib/python3.13/site-packages/crewai/agents/crew_agent_executor.py", line 154, in _invoke_loop
    answer = get_llm_response(
        llm=self.llm,
    ...<3 lines>...
        from_task=self.task
    )
  File "/home/vboxuser/Documents/Math-Odyssey/gen_formalizer/.venv/lib/python3.13/site-packages/crewai/utilities/agent_utils.py", line 160, in get_llm_response
    raise e
  File "/home/vboxuser/Documents/Math-Odyssey/gen_formalizer/.venv/lib/python3.13/site-packages/crewai/utilities/agent_utils.py", line 153, in get_llm_response
    answer = llm.call(
        messages,
    ...<2 lines>...
        from_agent=from_agent,
    )
  File "/home/vboxuser/Documents/Math-Odyssey/gen_formalizer/.venv/lib/python3.13/site-packages/crewai/llm.py", line 1030, in call
    return self._handle_non_streaming_response(
           ~~~~~~~~~~~~~~~~~~~~~~~~~~~~~~~~~~~^
        params, callbacks, available_functions, from_task, from_agent
        ^^^^^^^^^^^^^^^^^^^^^^^^^^^^^^^^^^^^^^^^^^^^^^^^^^^^^^^^^^^^^
    )
    ^
  File "/home/vboxuser/Documents/Math-Odyssey/gen_formalizer/.venv/lib/python3.13/site-packages/crewai/llm.py", line 813, in _handle_non_streaming_response
    response = litellm.completion(**params)
  File "/home/vboxuser/Documents/Math-Odyssey/gen_formalizer/.venv/lib/python3.13/site-packages/litellm/utils.py", line 1330, in wrapper
    raise e
  File "/home/vboxuser/Documents/Math-Odyssey/gen_formalizer/.venv/lib/python3.13/site-packages/litellm/utils.py", line 1205, in wrapper
    result = original_function(*args, **kwargs)
  File "/home/vboxuser/Documents/Math-Odyssey/gen_formalizer/.venv/lib/python3.13/site-packages/litellm/main.py", line 3427, in completion
    raise exception_type(
          ~~~~~~~~~~~~~~^
        model=model,
        ^^^^^^^^^^^^
    ...<3 lines>...
        extra_kwargs=kwargs,
        ^^^^^^^^^^^^^^^^^^^^
    )
    ^
  File "/home/vboxuser/Documents/Math-Odyssey/gen_formalizer/.venv/lib/python3.13/site-packages/litellm/litellm_core_utils/exception_mapping_utils.py", line 2301, in exception_type
    raise e
  File "/home/vboxuser/Documents/Math-Odyssey/gen_formalizer/.venv/lib/python3.13/site-packages/litellm/litellm_core_utils/exception_mapping_utils.py", line 1284, in exception_type
    raise litellm.InternalServerError(
    ...<4 lines>...
    )
litellm.exceptions.InternalServerError: litellm.InternalServerError: litellm.InternalServerError: VertexAIException - {
  "error": {
    "code": 503,
    "message": "The model is overloaded. Please try again later.",
    "status": "UNAVAILABLE"
  }
}


During handling of the above exception, another exception occurred:

Traceback (most recent call last):
  File "/home/vboxuser/Documents/Math-Odyssey/gen_formalizer/.venv/bin/run_crew", line 10, in <module>
    sys.exit(run(sys.argv[1], sys.argv[2]))
             ~~~^^^^^^^^^^^^^^^^^^^^^^^^^^
  File "/home/vboxuser/Documents/Math-Odyssey/gen_formalizer/src/gen_formalizer/main.py", line 37, in run
    raise Exception(f"An error occurred while running the crew: {e}")
Exception: An error occurred while running the crew: litellm.InternalServerError: litellm.InternalServerError: VertexAIException - {
  "error": {
    "code": 503,
    "message": "The model is overloaded. Please try again later.",
    "status": "UNAVAILABLE"
  }
}

An error occurred while running the crew: Command '['uv', 'run', 'run_crew', 'What is the exact value of $\\cos 22.5^{\\circ}$ ?\n\\begin{align*}\n\\text{A)}\\ & \\frac{\\sqrt{2+\\sqrt{2}}}{2}  &\n\\text{B)}\\ & -\\frac{\\sqrt{2+\\sqrt{2}}}{2} \\\\\n\\text{C)}\\ &  \\frac{\\sqrt{2-\\sqrt{2}}}{2} &\n\\text{D)}\\ & -\\frac{\\sqrt{2-\\sqrt{2}}}{2}\\\\\n\\end{align*}    \n\\end{problem}\n\\noindent', 'A \\\\\n\\noindent']' returned non-zero exit status 1.
Traceback (most recent call last):
  File "/home/vboxuser/Documents/Math-Odyssey/gen_formalizer/.venv/lib/python3.13/site-packages/litellm/llms/vertex_ai/gemini/vertex_and_google_ai_studio_gemini.py", line 1890, in completion
    response = client.post(url=url, headers=headers, json=data)  # type: ignore
  File "/home/vboxuser/Documents/Math-Odyssey/gen_formalizer/.venv/lib/python3.13/site-packages/litellm/llms/custom_httpx/http_handler.py", line 780, in post
    raise e
  File "/home/vboxuser/Documents/Math-Odyssey/gen_formalizer/.venv/lib/python3.13/site-packages/litellm/llms/custom_httpx/http_handler.py", line 762, in post
    response.raise_for_status()
    ~~~~~~~~~~~~~~~~~~~~~~~~~^^
  File "/home/vboxuser/Documents/Math-Odyssey/gen_formalizer/.venv/lib/python3.13/site-packages/httpx/_models.py", line 829, in raise_for_status
    raise HTTPStatusError(message, request=request, response=self)
httpx.HTTPStatusError: Server error '503 Service Unavailable' for url 'https://generativelanguage.googleapis.com/v1beta/models/gemini-2.5-flash:generateContent?key=AIzaSyDoL-8LOr6PUL1KLHCAQsSWl9uJ1PsMD7o'
For more information check: https://developer.mozilla.org/en-US/docs/Web/HTTP/Status/503

During handling of the above exception, another exception occurred:

Traceback (most recent call last):
  File "/home/vboxuser/Documents/Math-Odyssey/gen_formalizer/.venv/lib/python3.13/site-packages/litellm/main.py", line 2606, in completion
    response = vertex_chat_completion.completion(  # type: ignore
        model=model,
    ...<17 lines>...
        extra_headers=extra_headers,
    )
  File "/home/vboxuser/Documents/Math-Odyssey/gen_formalizer/.venv/lib/python3.13/site-packages/litellm/llms/vertex_ai/gemini/vertex_and_google_ai_studio_gemini.py", line 1894, in completion
    raise VertexAIError(
    ...<3 lines>...
    )
litellm.llms.vertex_ai.common_utils.VertexAIError: {
  "error": {
    "code": 503,
    "message": "The model is overloaded. Please try again later.",
    "status": "UNAVAILABLE"
  }
}


During handling of the above exception, another exception occurred:

Traceback (most recent call last):
  File "/home/vboxuser/Documents/Math-Odyssey/gen_formalizer/src/gen_formalizer/main.py", line 29, in run
    result = GenFormalizer().crew().kickoff(inputs=inputs)
  File "/home/vboxuser/Documents/Math-Odyssey/gen_formalizer/.venv/lib/python3.13/site-packages/crewai/crew.py", line 661, in kickoff
    result = self._run_sequential_process()
  File "/home/vboxuser/Documents/Math-Odyssey/gen_formalizer/.venv/lib/python3.13/site-packages/crewai/crew.py", line 772, in _run_sequential_process
    return self._execute_tasks(self.tasks)
           ~~~~~~~~~~~~~~~~~~~^^^^^^^^^^^^
  File "/home/vboxuser/Documents/Math-Odyssey/gen_formalizer/.venv/lib/python3.13/site-packages/crewai/crew.py", line 875, in _execute_tasks
    task_output = task.execute_sync(
        agent=agent_to_use,
        context=context,
        tools=cast(List[BaseTool], tools_for_task),
    )
  File "/home/vboxuser/Documents/Math-Odyssey/gen_formalizer/.venv/lib/python3.13/site-packages/crewai/task.py", line 382, in execute_sync
    return self._execute_core(agent, context, tools)
           ~~~~~~~~~~~~~~~~~~^^^^^^^^^^^^^^^^^^^^^^^
  File "/home/vboxuser/Documents/Math-Odyssey/gen_formalizer/.venv/lib/python3.13/site-packages/crewai/task.py", line 530, in _execute_core
    raise e  # Re-raise the exception after emitting the event
    ^^^^^^^
  File "/home/vboxuser/Documents/Math-Odyssey/gen_formalizer/.venv/lib/python3.13/site-packages/crewai/task.py", line 446, in _execute_core
    result = agent.execute_task(
        task=self,
        context=context,
        tools=tools,
    )
  File "/home/vboxuser/Documents/Math-Odyssey/gen_formalizer/.venv/lib/python3.13/site-packages/crewai/agent.py", line 475, in execute_task
    raise e
  File "/home/vboxuser/Documents/Math-Odyssey/gen_formalizer/.venv/lib/python3.13/site-packages/crewai/agent.py", line 451, in execute_task
    result = self._execute_without_timeout(task_prompt, task)
  File "/home/vboxuser/Documents/Math-Odyssey/gen_formalizer/.venv/lib/python3.13/site-packages/crewai/agent.py", line 547, in _execute_without_timeout
    return self.agent_executor.invoke(
           ~~~~~~~~~~~~~~~~~~~~~~~~~~^
        {
        ^
    ...<4 lines>...
        }
        ^
    )["output"]
    ^
  File "/home/vboxuser/Documents/Math-Odyssey/gen_formalizer/.venv/lib/python3.13/site-packages/crewai/agents/crew_agent_executor.py", line 114, in invoke
    formatted_answer = self._invoke_loop()
  File "/home/vboxuser/Documents/Math-Odyssey/gen_formalizer/.venv/lib/python3.13/site-packages/crewai/agents/crew_agent_executor.py", line 208, in _invoke_loop
    raise e
  File "/home/vboxuser/Documents/Math-Odyssey/gen_formalizer/.venv/lib/python3.13/site-packages/crewai/agents/crew_agent_executor.py", line 154, in _invoke_loop
    answer = get_llm_response(
        llm=self.llm,
    ...<3 lines>...
        from_task=self.task
    )
  File "/home/vboxuser/Documents/Math-Odyssey/gen_formalizer/.venv/lib/python3.13/site-packages/crewai/utilities/agent_utils.py", line 160, in get_llm_response
    raise e
  File "/home/vboxuser/Documents/Math-Odyssey/gen_formalizer/.venv/lib/python3.13/site-packages/crewai/utilities/agent_utils.py", line 153, in get_llm_response
    answer = llm.call(
        messages,
    ...<2 lines>...
        from_agent=from_agent,
    )
  File "/home/vboxuser/Documents/Math-Odyssey/gen_formalizer/.venv/lib/python3.13/site-packages/crewai/llm.py", line 1030, in call
    return self._handle_non_streaming_response(
           ~~~~~~~~~~~~~~~~~~~~~~~~~~~~~~~~~~~^
        params, callbacks, available_functions, from_task, from_agent
        ^^^^^^^^^^^^^^^^^^^^^^^^^^^^^^^^^^^^^^^^^^^^^^^^^^^^^^^^^^^^^
    )
    ^
  File "/home/vboxuser/Documents/Math-Odyssey/gen_formalizer/.venv/lib/python3.13/site-packages/crewai/llm.py", line 813, in _handle_non_streaming_response
    response = litellm.completion(**params)
  File "/home/vboxuser/Documents/Math-Odyssey/gen_formalizer/.venv/lib/python3.13/site-packages/litellm/utils.py", line 1330, in wrapper
    raise e
  File "/home/vboxuser/Documents/Math-Odyssey/gen_formalizer/.venv/lib/python3.13/site-packages/litellm/utils.py", line 1205, in wrapper
    result = original_function(*args, **kwargs)
  File "/home/vboxuser/Documents/Math-Odyssey/gen_formalizer/.venv/lib/python3.13/site-packages/litellm/main.py", line 3427, in completion
    raise exception_type(
          ~~~~~~~~~~~~~~^
        model=model,
        ^^^^^^^^^^^^
    ...<3 lines>...
        extra_kwargs=kwargs,
        ^^^^^^^^^^^^^^^^^^^^
    )
    ^
  File "/home/vboxuser/Documents/Math-Odyssey/gen_formalizer/.venv/lib/python3.13/site-packages/litellm/litellm_core_utils/exception_mapping_utils.py", line 2301, in exception_type
    raise e
  File "/home/vboxuser/Documents/Math-Odyssey/gen_formalizer/.venv/lib/python3.13/site-packages/litellm/litellm_core_utils/exception_mapping_utils.py", line 1284, in exception_type
    raise litellm.InternalServerError(
    ...<4 lines>...
    )
litellm.exceptions.InternalServerError: litellm.InternalServerError: litellm.InternalServerError: VertexAIException - {
  "error": {
    "code": 503,
    "message": "The model is overloaded. Please try again later.",
    "status": "UNAVAILABLE"
  }
}


During handling of the above exception, another exception occurred:

Traceback (most recent call last):
  File "/home/vboxuser/Documents/Math-Odyssey/gen_formalizer/.venv/bin/run_crew", line 10, in <module>
    sys.exit(run(sys.argv[1], sys.argv[2]))
             ~~~^^^^^^^^^^^^^^^^^^^^^^^^^^
  File "/home/vboxuser/Documents/Math-Odyssey/gen_formalizer/src/gen_formalizer/main.py", line 37, in run
    raise Exception(f"An error occurred while running the crew: {e}")
Exception: An error occurred while running the crew: litellm.InternalServerError: litellm.InternalServerError: VertexAIException - {
  "error": {
    "code": 503,
    "message": "The model is overloaded. Please try again later.",
    "status": "UNAVAILABLE"
  }
}

An error occurred while running the crew: Command '['uv', 'run', 'run_crew', 'Find the distance traveled in the first four seconds for a particle whose velocity is given by $v(t)=7 e^{-t^{2}}$, where $t$ stands for time.\n\\begin{align*}\n\\text{A)}\\ &  0.976 &\n\\text{B)}\\ & 6.204 \\\\\n\\text{C)}\\ &  6.359 &\n\\text{D)}\\ & 12.720\\\\\n\\text{E)}\\ & 7.000 &\n\\end{align*}    \n\\end{problem}\n\\noindent', 'B\\\\\n\\noindent']' returned non-zero exit status 1.
wrong: 20
correct: 80
\n
wrong: 22
correct: 78
\n
Usage: crewai run [OPTIONS] QUESTION ANSWER
Try 'crewai run --help' for help.

Error: No such option: -1
Traceback (most recent call last):
  File "/home/vboxuser/Documents/Math-Odyssey/gen_formalizer/.venv/lib/python3.13/site-packages/litellm/llms/vertex_ai/gemini/vertex_and_google_ai_studio_gemini.py", line 1890, in completion
    response = client.post(url=url, headers=headers, json=data)  # type: ignore
  File "/home/vboxuser/Documents/Math-Odyssey/gen_formalizer/.venv/lib/python3.13/site-packages/litellm/llms/custom_httpx/http_handler.py", line 780, in post
    raise e
  File "/home/vboxuser/Documents/Math-Odyssey/gen_formalizer/.venv/lib/python3.13/site-packages/litellm/llms/custom_httpx/http_handler.py", line 762, in post
    response.raise_for_status()
    ~~~~~~~~~~~~~~~~~~~~~~~~~^^
  File "/home/vboxuser/Documents/Math-Odyssey/gen_formalizer/.venv/lib/python3.13/site-packages/httpx/_models.py", line 829, in raise_for_status
    raise HTTPStatusError(message, request=request, response=self)
httpx.HTTPStatusError: Server error '503 Service Unavailable' for url 'https://generativelanguage.googleapis.com/v1beta/models/gemini-2.5-flash:generateContent?key=AIzaSyDoL-8LOr6PUL1KLHCAQsSWl9uJ1PsMD7o'
For more information check: https://developer.mozilla.org/en-US/docs/Web/HTTP/Status/503

During handling of the above exception, another exception occurred:

Traceback (most recent call last):
  File "/home/vboxuser/Documents/Math-Odyssey/gen_formalizer/.venv/lib/python3.13/site-packages/litellm/main.py", line 2606, in completion
    response = vertex_chat_completion.completion(  # type: ignore
        model=model,
    ...<17 lines>...
        extra_headers=extra_headers,
    )
  File "/home/vboxuser/Documents/Math-Odyssey/gen_formalizer/.venv/lib/python3.13/site-packages/litellm/llms/vertex_ai/gemini/vertex_and_google_ai_studio_gemini.py", line 1894, in completion
    raise VertexAIError(
    ...<3 lines>...
    )
litellm.llms.vertex_ai.common_utils.VertexAIError: {
  "error": {
    "code": 503,
    "message": "The model is overloaded. Please try again later.",
    "status": "UNAVAILABLE"
  }
}


During handling of the above exception, another exception occurred:

Traceback (most recent call last):
  File "/home/vboxuser/Documents/Math-Odyssey/gen_formalizer/src/gen_formalizer/main.py", line 29, in run
    result = GenFormalizer().crew().kickoff(inputs=inputs)
  File "/home/vboxuser/Documents/Math-Odyssey/gen_formalizer/.venv/lib/python3.13/site-packages/crewai/crew.py", line 661, in kickoff
    result = self._run_sequential_process()
  File "/home/vboxuser/Documents/Math-Odyssey/gen_formalizer/.venv/lib/python3.13/site-packages/crewai/crew.py", line 772, in _run_sequential_process
    return self._execute_tasks(self.tasks)
           ~~~~~~~~~~~~~~~~~~~^^^^^^^^^^^^
  File "/home/vboxuser/Documents/Math-Odyssey/gen_formalizer/.venv/lib/python3.13/site-packages/crewai/crew.py", line 875, in _execute_tasks
    task_output = task.execute_sync(
        agent=agent_to_use,
        context=context,
        tools=cast(List[BaseTool], tools_for_task),
    )
  File "/home/vboxuser/Documents/Math-Odyssey/gen_formalizer/.venv/lib/python3.13/site-packages/crewai/task.py", line 382, in execute_sync
    return self._execute_core(agent, context, tools)
           ~~~~~~~~~~~~~~~~~~^^^^^^^^^^^^^^^^^^^^^^^
  File "/home/vboxuser/Documents/Math-Odyssey/gen_formalizer/.venv/lib/python3.13/site-packages/crewai/task.py", line 530, in _execute_core
    raise e  # Re-raise the exception after emitting the event
    ^^^^^^^
  File "/home/vboxuser/Documents/Math-Odyssey/gen_formalizer/.venv/lib/python3.13/site-packages/crewai/task.py", line 446, in _execute_core
    result = agent.execute_task(
        task=self,
        context=context,
        tools=tools,
    )
  File "/home/vboxuser/Documents/Math-Odyssey/gen_formalizer/.venv/lib/python3.13/site-packages/crewai/agent.py", line 475, in execute_task
    raise e
  File "/home/vboxuser/Documents/Math-Odyssey/gen_formalizer/.venv/lib/python3.13/site-packages/crewai/agent.py", line 451, in execute_task
    result = self._execute_without_timeout(task_prompt, task)
  File "/home/vboxuser/Documents/Math-Odyssey/gen_formalizer/.venv/lib/python3.13/site-packages/crewai/agent.py", line 547, in _execute_without_timeout
    return self.agent_executor.invoke(
           ~~~~~~~~~~~~~~~~~~~~~~~~~~^
        {
        ^
    ...<4 lines>...
        }
        ^
    )["output"]
    ^
  File "/home/vboxuser/Documents/Math-Odyssey/gen_formalizer/.venv/lib/python3.13/site-packages/crewai/agents/crew_agent_executor.py", line 114, in invoke
    formatted_answer = self._invoke_loop()
  File "/home/vboxuser/Documents/Math-Odyssey/gen_formalizer/.venv/lib/python3.13/site-packages/crewai/agents/crew_agent_executor.py", line 208, in _invoke_loop
    raise e
  File "/home/vboxuser/Documents/Math-Odyssey/gen_formalizer/.venv/lib/python3.13/site-packages/crewai/agents/crew_agent_executor.py", line 154, in _invoke_loop
    answer = get_llm_response(
        llm=self.llm,
    ...<3 lines>...
        from_task=self.task
    )
  File "/home/vboxuser/Documents/Math-Odyssey/gen_formalizer/.venv/lib/python3.13/site-packages/crewai/utilities/agent_utils.py", line 160, in get_llm_response
    raise e
  File "/home/vboxuser/Documents/Math-Odyssey/gen_formalizer/.venv/lib/python3.13/site-packages/crewai/utilities/agent_utils.py", line 153, in get_llm_response
    answer = llm.call(
        messages,
    ...<2 lines>...
        from_agent=from_agent,
    )
  File "/home/vboxuser/Documents/Math-Odyssey/gen_formalizer/.venv/lib/python3.13/site-packages/crewai/llm.py", line 1030, in call
    return self._handle_non_streaming_response(
           ~~~~~~~~~~~~~~~~~~~~~~~~~~~~~~~~~~~^
        params, callbacks, available_functions, from_task, from_agent
        ^^^^^^^^^^^^^^^^^^^^^^^^^^^^^^^^^^^^^^^^^^^^^^^^^^^^^^^^^^^^^
    )
    ^
  File "/home/vboxuser/Documents/Math-Odyssey/gen_formalizer/.venv/lib/python3.13/site-packages/crewai/llm.py", line 813, in _handle_non_streaming_response
    response = litellm.completion(**params)
  File "/home/vboxuser/Documents/Math-Odyssey/gen_formalizer/.venv/lib/python3.13/site-packages/litellm/utils.py", line 1330, in wrapper
    raise e
  File "/home/vboxuser/Documents/Math-Odyssey/gen_formalizer/.venv/lib/python3.13/site-packages/litellm/utils.py", line 1205, in wrapper
    result = original_function(*args, **kwargs)
  File "/home/vboxuser/Documents/Math-Odyssey/gen_formalizer/.venv/lib/python3.13/site-packages/litellm/main.py", line 3427, in completion
    raise exception_type(
          ~~~~~~~~~~~~~~^
        model=model,
        ^^^^^^^^^^^^
    ...<3 lines>...
        extra_kwargs=kwargs,
        ^^^^^^^^^^^^^^^^^^^^
    )
    ^
  File "/home/vboxuser/Documents/Math-Odyssey/gen_formalizer/.venv/lib/python3.13/site-packages/litellm/litellm_core_utils/exception_mapping_utils.py", line 2301, in exception_type
    raise e
  File "/home/vboxuser/Documents/Math-Odyssey/gen_formalizer/.venv/lib/python3.13/site-packages/litellm/litellm_core_utils/exception_mapping_utils.py", line 1284, in exception_type
    raise litellm.InternalServerError(
    ...<4 lines>...
    )
litellm.exceptions.InternalServerError: litellm.InternalServerError: litellm.InternalServerError: VertexAIException - {
  "error": {
    "code": 503,
    "message": "The model is overloaded. Please try again later.",
    "status": "UNAVAILABLE"
  }
}


During handling of the above exception, another exception occurred:

Traceback (most recent call last):
  File "/home/vboxuser/Documents/Math-Odyssey/gen_formalizer/.venv/bin/run_crew", line 10, in <module>
    sys.exit(run(sys.argv[1], sys.argv[2]))
             ~~~^^^^^^^^^^^^^^^^^^^^^^^^^^
  File "/home/vboxuser/Documents/Math-Odyssey/gen_formalizer/src/gen_formalizer/main.py", line 37, in run
    raise Exception(f"An error occurred while running the crew: {e}")
Exception: An error occurred while running the crew: litellm.InternalServerError: litellm.InternalServerError: VertexAIException - {
  "error": {
    "code": 503,
    "message": "The model is overloaded. Please try again later.",
    "status": "UNAVAILABLE"
  }
}

An error occurred while running the crew: Command '['uv', 'run', 'run_crew', 'Choose all the following that have an end behavior as $x \\rightarrow \\infty, f(x) \\rightarrow \\infty$. NOTE: You may choose more than one.\n\\begin{align*}\n\\text{A)}\\ & f(x)=-x^{4}+3 x^{2}-x-7 &\n\\text{B)}\\ & f(x)=x^{3}+5 x+1  \\\\\n\\text{C)}\\ & f(x)=-3 x^{5}+2 x^{3}+9 x-4 &\n\\text{D)}\\ & f(x)=-2(x-7)^{2}+4\\\\\n\\text{E)}\\ & f(x)=-3 x+2 &\n\\text{F)}\\ & f(x)=(x-8)^{2}+2\\\\\n\\end{align*}    \n\\end{problem}\n\\noindent', 'B, F\\\\\n\\noindent']' returned non-zero exit status 1.
Usage: crewai run [OPTIONS] QUESTION ANSWER
Try 'crewai run --help' for help.

Error: No such option: -4
wrong: 16
correct: 84
\n
